package com.universeCraft.generation;

import java.util.Random;

import com.universeCraft.blocks.ModBlocks;

import net.minecraft.init.Blocks;
import net.minecraft.world.World;
import net.minecraft.world.gen.feature.WorldGenerator;

public class WorldGenSmallMeteor extends WorldGenerator{
	
	public boolean generate(World world, Random rand, int x, int y, int z) 
	{
		world.setBlock(x + 0, y + 3, z + 4, Blocks.obsidian);
		world.setBlock(x + 0, y + 3, z + 5, Blocks.obsidian);
		world.setBlock(x + 0, y + 3, z + 6, Blocks.obsidian);
		world.setBlock(x + 0, y + 4, z + 3, Blocks.obsidian);
		world.setBlock(x + 0, y + 4, z + 4, Blocks.obsidian);
		world.setBlock(x + 0, y + 4, z + 5, Blocks.obsidian);
		world.setBlock(x + 0, y + 4, z + 6, Blocks.obsidian);
		world.setBlock(x + 0, y + 4, z + 7, Blocks.obsidian);
		world.setBlock(x + 0, y + 5, z + 3, Blocks.obsidian);
		world.setBlock(x + 0, y + 5, z + 4, ModBlocks.metadataBlocks, 3, 2);
		world.setBlock(x + 0, y + 5, z + 5, Blocks.obsidian);
		world.setBlock(x + 0, y + 5, z + 6, Blocks.obsidian);
		world.setBlock(x + 0, y + 5, z + 7, Blocks.obsidian);
		world.setBlock(x + 0, y + 6, z + 3, Blocks.obsidian);
		world.setBlock(x + 0, y + 6, z + 4, Blocks.obsidian);
		world.setBlock(x + 0, y + 6, z + 5, ModBlocks.metadataBlocks, 3, 2);
		world.setBlock(x + 0, y + 6, z + 6, Blocks.obsidian);
		world.setBlock(x + 0, y + 6, z + 7, Blocks.obsidian);
		world.setBlock(x + 0, y + 7, z + 4, ModBlocks.metadataBlocks, 3, 2);
		world.setBlock(x + 0, y + 7, z + 5, Blocks.obsidian);
		world.setBlock(x + 0, y + 7, z + 6, Blocks.obsidian);
		world.setBlock(x + 1, y + 2, z + 3, Blocks.obsidian);
		world.setBlock(x + 1, y + 2, z + 4, ModBlocks.metadataBlocks, 7, 2);
		world.setBlock(x + 1, y + 2, z + 5, ModBlocks.metadataBlocks, 7, 2);
		world.setBlock(x + 1, y + 2, z + 6, ModBlocks.metadataBlocks, 7, 2);
		world.setBlock(x + 1, y + 2, z + 7, ModBlocks.metadataBlocks, 3, 2);
		world.setBlock(x + 1, y + 3, z + 2, Blocks.obsidian);
		world.setBlock(x + 1, y + 3, z + 3, ModBlocks.metadataBlocks, 7, 2);
		world.setBlock(x + 1, y + 3, z + 4, ModBlocks.metadataBlocks, 7, 2);
		world.setBlock(x + 1, y + 3, z + 5, ModBlocks.metadataBlocks, 7, 2);
		world.setBlock(x + 1, y + 3, z + 6, ModBlocks.metadataBlocks, 7, 2);
		world.setBlock(x + 1, y + 3, z + 7, ModBlocks.metadataBlocks, 7, 2);
		world.setBlock(x + 1, y + 3, z + 8, Blocks.obsidian);
		world.setBlock(x + 1, y + 4, z + 2, Blocks.obsidian);
		world.setBlock(x + 1, y + 4, z + 3, ModBlocks.metadataBlocks, 7, 2);
		world.setBlock(x + 1, y + 4, z + 4, ModBlocks.metadataBlocks, 3, 2);
		world.setBlock(x + 1, y + 4, z + 5, ModBlocks.metadataBlocks, 7, 2);
		world.setBlock(x + 1, y + 4, z + 6, ModBlocks.metadataBlocks, 7, 2);
		world.setBlock(x + 1, y + 4, z + 7, ModBlocks.metadataBlocks, 3, 2);
		world.setBlock(x + 1, y + 4, z + 8, Blocks.obsidian);
		world.setBlock(x + 1, y + 5, z + 2, ModBlocks.metadataBlocks, 3, 2);
		world.setBlock(x + 1, y + 5, z + 3, ModBlocks.metadataBlocks, 3, 2);
		world.setBlock(x + 1, y + 5, z + 4, ModBlocks.metadataBlocks, 3, 2);
		world.setBlock(x + 1, y + 5, z + 5, ModBlocks.metadataBlocks, 3, 2);
		world.setBlock(x + 1, y + 5, z + 6, ModBlocks.metadataBlocks, 3, 2);
		world.setBlock(x + 1, y + 5, z + 7, ModBlocks.metadataBlocks, 7, 2);
		world.setBlock(x + 1, y + 5, z + 8, ModBlocks.metadataBlocks, 7, 2);
		world.setBlock(x + 1, y + 6, z + 2, Blocks.obsidian);
		world.setBlock(x + 1, y + 6, z + 4, ModBlocks.metadataBlocks, 3, 2);
		world.setBlock(x + 1, y + 6, z + 5, ModBlocks.metadataBlocks, 2, 2);
		world.setBlock(x + 1, y + 6, z + 6, ModBlocks.metadataBlocks, 3, 2);
		world.setBlock(x + 1, y + 6, z + 7, ModBlocks.metadataBlocks, 7, 2);
		world.setBlock(x + 1, y + 6, z + 8, ModBlocks.metadataBlocks, 3, 2);
		world.setBlock(x + 1, y + 7, z + 2, Blocks.obsidian);
		world.setBlock(x + 1, y + 7, z + 3, Blocks.obsidian);
		world.setBlock(x + 1, y + 7, z + 5, ModBlocks.metadataBlocks, 3, 2);
		world.setBlock(x + 1, y + 7, z + 7, ModBlocks.metadataBlocks, 7, 2);
		world.setBlock(x + 1, y + 7, z + 8, Blocks.obsidian);
		world.setBlock(x + 1, y + 8, z + 3, Blocks.obsidian);
		world.setBlock(x + 1, y + 8, z + 4, Blocks.obsidian);
		world.setBlock(x + 1, y + 8, z + 5, Blocks.obsidian);
		world.setBlock(x + 1, y + 8, z + 6, Blocks.obsidian);
		world.setBlock(x + 1, y + 8, z + 7, Blocks.obsidian);
		world.setBlock(x + 2, y + 1, z + 3, Blocks.obsidian);
		world.setBlock(x + 2, y + 1, z + 4, ModBlocks.metadataBlocks, 7, 2);
		world.setBlock(x + 2, y + 1, z + 5, ModBlocks.metadataBlocks, 7, 2);
		world.setBlock(x + 2, y + 1, z + 6, Blocks.obsidian);
		world.setBlock(x + 2, y + 1, z + 7, Blocks.obsidian);
		world.setBlock(x + 2, y + 2, z + 2, Blocks.obsidian);
		world.setBlock(x + 2, y + 2, z + 3, ModBlocks.metadataBlocks, 3, 2);
		world.setBlock(x + 2, y + 2, z + 4, ModBlocks.metadataBlocks, 7, 2);
		world.setBlock(x + 2, y + 2, z + 5, ModBlocks.metadataBlocks, 3, 2);
		world.setBlock(x + 2, y + 2, z + 6, ModBlocks.metadataBlocks, 7, 2);
		world.setBlock(x + 2, y + 2, z + 8, Blocks.obsidian);
		world.setBlock(x + 2, y + 3, z + 1, Blocks.obsidian);
		world.setBlock(x + 2, y + 3, z + 2, ModBlocks.metadataBlocks, 7, 2);
		world.setBlock(x + 2, y + 3, z + 3, ModBlocks.metadataBlocks, 7, 2);
		world.setBlock(x + 2, y + 3, z + 4, ModBlocks.metadataBlocks, 7, 2);
		world.setBlock(x + 2, y + 3, z + 5, ModBlocks.metadataBlocks, 7, 2);
		world.setBlock(x + 2, y + 3, z + 6, ModBlocks.metadataBlocks, 7, 2);
		world.setBlock(x + 2, y + 3, z + 7, ModBlocks.metadataBlocks, 3, 2);
		world.setBlock(x + 2, y + 3, z + 9, Blocks.obsidian);
		world.setBlock(x + 2, y + 4, z + 1, Blocks.obsidian);
		world.setBlock(x + 2, y + 4, z + 2, ModBlocks.metadataBlocks, 7, 2);
		world.setBlock(x + 2, y + 4, z + 3, ModBlocks.metadataBlocks, 3, 2);
		world.setBlock(x + 2, y + 4, z + 4, ModBlocks.metadataBlocks, 7, 2);
		world.setBlock(x + 2, y + 4, z + 5, ModBlocks.metadataBlocks, 7, 2);
		world.setBlock(x + 2, y + 4, z + 6, ModBlocks.metadataBlocks, 7, 2);
		world.setBlock(x + 2, y + 4, z + 7, ModBlocks.metadataBlocks, 7, 2);
		world.setBlock(x + 2, y + 4, z + 8, ModBlocks.metadataBlocks, 3, 2);
		world.setBlock(x + 2, y + 4, z + 9, Blocks.obsidian);
		world.setBlock(x + 2, y + 5, z + 1, Blocks.obsidian);
		world.setBlock(x + 2, y + 5, z + 2, ModBlocks.metadataBlocks, 7, 2);
		world.setBlock(x + 2, y + 5, z + 3, ModBlocks.metadataBlocks, 3, 2);
		world.setBlock(x + 2, y + 5, z + 4, ModBlocks.metadataBlocks, 3, 2);
		world.setBlock(x + 2, y + 5, z + 5, ModBlocks.metadataBlocks, 3, 2);
		world.setBlock(x + 2, y + 5, z + 6, ModBlocks.metadataBlocks, 7, 2);
		world.setBlock(x + 2, y + 5, z + 7, ModBlocks.metadataBlocks, 7, 2);
		world.setBlock(x + 2, y + 5, z + 8, ModBlocks.metadataBlocks, 7, 2);
		world.setBlock(x + 2, y + 5, z + 9, ModBlocks.metadataBlocks, 2, 2);
		world.setBlock(x + 2, y + 6, z + 1, Blocks.obsidian);
		world.setBlock(x + 2, y + 6, z + 2, ModBlocks.metadataBlocks, 7, 2);
		world.setBlock(x + 2, y + 6, z + 3, ModBlocks.metadataBlocks, 3, 2);
		world.setBlock(x + 2, y + 6, z + 4, ModBlocks.metadataBlocks, 3, 2);
		world.setBlock(x + 2, y + 6, z + 5, ModBlocks.metadataBlocks, 3, 2);
		world.setBlock(x + 2, y + 6, z + 6, ModBlocks.metadataBlocks, 3, 2);
		world.setBlock(x + 2, y + 6, z + 7, ModBlocks.metadataBlocks, 7, 2);
		world.setBlock(x + 2, y + 6, z + 8, ModBlocks.metadataBlocks, 7, 2);
		world.setBlock(x + 2, y + 6, z + 9, Blocks.obsidian);
		world.setBlock(x + 2, y + 7, z + 1, Blocks.obsidian);
		world.setBlock(x + 2, y + 7, z + 3, ModBlocks.metadataBlocks, 3, 2);
		world.setBlock(x + 2, y + 7, z + 4, ModBlocks.metadataBlocks, 3, 2);
		world.setBlock(x + 2, y + 7, z + 5, ModBlocks.metadataBlocks, 3, 2);
		world.setBlock(x + 2, y + 7, z + 6, ModBlocks.metadataBlocks, 3, 2);
		world.setBlock(x + 2, y + 7, z + 7, ModBlocks.metadataBlocks, 7, 2);
		world.setBlock(x + 2, y + 7, z + 8, ModBlocks.metadataBlocks, 7, 2);
		world.setBlock(x + 2, y + 7, z + 9, Blocks.obsidian);
		world.setBlock(x + 2, y + 8, z + 2, Blocks.obsidian);
		world.setBlock(x + 2, y + 8, z + 4, ModBlocks.metadataBlocks, 3, 2);
		world.setBlock(x + 2, y + 8, z + 5, ModBlocks.metadataBlocks, 3, 2);
		world.setBlock(x + 2, y + 8, z + 6, ModBlocks.metadataBlocks, 3, 2);
		world.setBlock(x + 2, y + 8, z + 8, Blocks.obsidian);
		world.setBlock(x + 2, y + 9, z + 3, Blocks.obsidian);
		world.setBlock(x + 2, y + 9, z + 4, Blocks.obsidian);
		world.setBlock(x + 2, y + 9, z + 5, Blocks.obsidian);
		world.setBlock(x + 2, y + 9, z + 6, Blocks.obsidian);
		world.setBlock(x + 2, y + 9, z + 7, Blocks.obsidian);
		world.setBlock(x + 3, y + 0, z + 4, ModBlocks.metadataBlocks, 7, 2);
		world.setBlock(x + 3, y + 0, z + 5, ModBlocks.metadataBlocks, 7, 2);
		world.setBlock(x + 3, y + 0, z + 6, ModBlocks.metadataBlocks, 7, 2);
		world.setBlock(x + 3, y + 1, z + 2, Blocks.obsidian);
		world.setBlock(x + 3, y + 1, z + 3, Blocks.obsidian);
		world.setBlock(x + 3, y + 1, z + 4, ModBlocks.metadataBlocks, 7, 2);
		world.setBlock(x + 3, y + 1, z + 5, ModBlocks.metadataBlocks, 7, 2);
		world.setBlock(x + 3, y + 1, z + 6, ModBlocks.metadataBlocks, 7, 2);
		world.setBlock(x + 3, y + 1, z + 7, Blocks.obsidian);
		world.setBlock(x + 3, y + 1, z + 8, ModBlocks.metadataBlocks, 3, 2);
		world.setBlock(x + 3, y + 2, z + 1, Blocks.obsidian);
		world.setBlock(x + 3, y + 2, z + 3, ModBlocks.metadataBlocks, 3, 2);
		world.setBlock(x + 3, y + 2, z + 4, ModBlocks.metadataBlocks, 7, 2);
		world.setBlock(x + 3, y + 2, z + 5, ModBlocks.metadataBlocks, 7, 2);
		world.setBlock(x + 3, y + 2, z + 6, ModBlocks.metadataBlocks, 3, 2);
		world.setBlock(x + 3, y + 2, z + 7, ModBlocks.metadataBlocks, 3, 2);
		world.setBlock(x + 3, y + 2, z + 9, Blocks.obsidian);
		world.setBlock(x + 3, y + 3, z + 1, Blocks.obsidian);
		world.setBlock(x + 3, y + 3, z + 2, ModBlocks.metadataBlocks, 3, 2);
		world.setBlock(x + 3, y + 3, z + 3, ModBlocks.metadataBlocks, 7, 2);
		world.setBlock(x + 3, y + 3, z + 4, ModBlocks.metadataBlocks, 7, 2);
		world.setBlock(x + 3, y + 3, z + 5, ModBlocks.metadataBlocks, 7, 2);
		world.setBlock(x + 3, y + 3, z + 6, ModBlocks.metadataBlocks, 7, 2);
		world.setBlock(x + 3, y + 3, z + 7, ModBlocks.metadataBlocks, 3, 2);
		world.setBlock(x + 3, y + 3, z + 8, ModBlocks.metadataBlocks, 3, 2);
		world.setBlock(x + 3, y + 3, z + 9, Blocks.obsidian);
		world.setBlock(x + 3, y + 4, z + 0, Blocks.obsidian);
		world.setBlock(x + 3, y + 4, z + 1, ModBlocks.metadataBlocks, 7, 2);
		world.setBlock(x + 3, y + 4, z + 2, ModBlocks.metadataBlocks, 7, 2);
		world.setBlock(x + 3, y + 4, z + 3, ModBlocks.metadataBlocks, 7, 2);
		world.setBlock(x + 3, y + 4, z + 4, ModBlocks.metadataBlocks, 3, 2);
		world.setBlock(x + 3, y + 4, z + 5, ModBlocks.metadataBlocks, 7, 2);
		world.setBlock(x + 3, y + 4, z + 6, ModBlocks.metadataBlocks, 7, 2);
		world.setBlock(x + 3, y + 4, z + 7, ModBlocks.metadataBlocks, 3, 2);
		world.setBlock(x + 3, y + 4, z + 8, ModBlocks.metadataBlocks, 3, 2);
		world.setBlock(x + 3, y + 4, z + 10, Blocks.obsidian);
		world.setBlock(x + 3, y + 5, z + 0, Blocks.obsidian);
		world.setBlock(x + 3, y + 5, z + 1, ModBlocks.metadataBlocks, 7, 2);
		world.setBlock(x + 3, y + 5, z + 2, ModBlocks.metadataBlocks, 7, 2);
		world.setBlock(x + 3, y + 5, z + 3, ModBlocks.metadataBlocks, 7, 2);
		world.setBlock(x + 3, y + 5, z + 4, ModBlocks.metadataBlocks, 7, 2);
		world.setBlock(x + 3, y + 5, z + 5, ModBlocks.metadataBlocks, 3, 2);
		world.setBlock(x + 3, y + 5, z + 6, ModBlocks.metadataBlocks, 3, 2);
		world.setBlock(x + 3, y + 5, z + 7, ModBlocks.metadataBlocks, 7, 2);
		world.setBlock(x + 3, y + 5, z + 8, ModBlocks.metadataBlocks, 3, 2);
		world.setBlock(x + 3, y + 5, z + 9, ModBlocks.metadataBlocks, 7, 2);
		world.setBlock(x + 3, y + 5, z + 10, ModBlocks.metadataBlocks, 7, 2);
		world.setBlock(x + 3, y + 6, z + 0, ModBlocks.metadataBlocks, 3, 2);
		world.setBlock(x + 3, y + 6, z + 2, ModBlocks.metadataBlocks, 7, 2);
		world.setBlock(x + 3, y + 6, z + 3, ModBlocks.metadataBlocks, 7, 2);
		world.setBlock(x + 3, y + 6, z + 4, ModBlocks.metadataBlocks, 3, 2);
		world.setBlock(x + 3, y + 6, z + 5, ModBlocks.metadataBlocks, 3, 2);
		world.setBlock(x + 3, y + 6, z + 6, ModBlocks.metadataBlocks, 7, 2);
		world.setBlock(x + 3, y + 6, z + 7, ModBlocks.metadataBlocks, 7, 2);
		world.setBlock(x + 3, y + 6, z + 8, ModBlocks.metadataBlocks, 7, 2);
		world.setBlock(x + 3, y + 6, z + 9, ModBlocks.metadataBlocks, 7, 2);
		world.setBlock(x + 3, y + 6, z + 10, ModBlocks.metadataBlocks, 7, 2);
		world.setBlock(x + 3, y + 7, z + 1, Blocks.obsidian);
		world.setBlock(x + 3, y + 7, z + 2, ModBlocks.metadataBlocks, 3, 2);
		world.setBlock(x + 3, y + 7, z + 3, ModBlocks.metadataBlocks, 3, 2);
		world.setBlock(x + 3, y + 7, z + 4, ModBlocks.metadataBlocks, 3, 2);
		world.setBlock(x + 3, y + 7, z + 5, ModBlocks.metadataBlocks, 3, 2);
		world.setBlock(x + 3, y + 7, z + 6, ModBlocks.metadataBlocks, 3, 2);
		world.setBlock(x + 3, y + 7, z + 7, ModBlocks.metadataBlocks, 7, 2);
		world.setBlock(x + 3, y + 7, z + 8, ModBlocks.metadataBlocks, 7, 2);
		world.setBlock(x + 3, y + 7, z + 9, ModBlocks.metadataBlocks, 7, 2);
		world.setBlock(x + 3, y + 8, z + 1, Blocks.obsidian);
		world.setBlock(x + 3, y + 8, z + 3, ModBlocks.metadataBlocks, 3, 2);
		world.setBlock(x + 3, y + 8, z + 4, ModBlocks.metadataBlocks, 3, 2);
		world.setBlock(x + 3, y + 8, z + 5, ModBlocks.metadataBlocks, 3, 2);
		world.setBlock(x + 3, y + 8, z + 6, ModBlocks.metadataBlocks, 3, 2);
		world.setBlock(x + 3, y + 8, z + 7, ModBlocks.metadataBlocks, 7, 2);
		world.setBlock(x + 3, y + 8, z + 8, ModBlocks.metadataBlocks, 3, 2);
		world.setBlock(x + 3, y + 8, z + 9, Blocks.obsidian);
		world.setBlock(x + 3, y + 9, z + 2, Blocks.obsidian);
		world.setBlock(x + 3, y + 9, z + 3, Blocks.obsidian);
		world.setBlock(x + 3, y + 9, z + 5, ModBlocks.metadataBlocks, 3, 2);
		world.setBlock(x + 3, y + 9, z + 7, ModBlocks.metadataBlocks, 7, 2);
		world.setBlock(x + 3, y + 9, z + 8, Blocks.obsidian);
		world.setBlock(x + 3, y + 10, z + 4, Blocks.obsidian);
		world.setBlock(x + 3, y + 10, z + 5, Blocks.obsidian);
		world.setBlock(x + 3, y + 10, z + 6, Blocks.obsidian);
		world.setBlock(x + 4, y + 0, z + 3, Blocks.obsidian);
		world.setBlock(x + 4, y + 0, z + 4, ModBlocks.metadataBlocks, 7, 2);
		world.setBlock(x + 4, y + 0, z + 5, ModBlocks.metadataBlocks, 7, 2);
		world.setBlock(x + 4, y + 0, z + 6, ModBlocks.metadataBlocks, 7, 2);
		world.setBlock(x + 4, y + 0, z + 7, Blocks.obsidian);
		world.setBlock(x + 4, y + 1, z + 2, Blocks.obsidian);
		world.setBlock(x + 4, y + 1, z + 4, ModBlocks.metadataBlocks, 7, 2);
		world.setBlock(x + 4, y + 1, z + 5, ModBlocks.metadataBlocks, 3, 2);
		world.setBlock(x + 4, y + 1, z + 6, ModBlocks.metadataBlocks, 7, 2);
		world.setBlock(x + 4, y + 1, z + 8, Blocks.obsidian);
		world.setBlock(x + 4, y + 2, z + 1, Blocks.obsidian);
		world.setBlock(x + 4, y + 2, z + 2, ModBlocks.metadataBlocks, 3, 2);
		world.setBlock(x + 4, y + 2, z + 3, ModBlocks.metadataBlocks, 3, 2);
		world.setBlock(x + 4, y + 2, z + 4, ModBlocks.metadataBlocks, 7, 2);
		world.setBlock(x + 4, y + 2, z + 5, ModBlocks.metadataBlocks, 7, 2);
		world.setBlock(x + 4, y + 2, z + 6, ModBlocks.metadataBlocks, 7, 2);
		world.setBlock(x + 4, y + 2, z + 7, ModBlocks.metadataBlocks, 3, 2);
		world.setBlock(x + 4, y + 2, z + 8, ModBlocks.metadataBlocks, 3, 2);
		world.setBlock(x + 4, y + 2, z + 9, Blocks.obsidian);
		world.setBlock(x + 4, y + 3, z + 0, Blocks.obsidian);
		world.setBlock(x + 4, y + 3, z + 2, ModBlocks.metadataBlocks, 3, 2);
		world.setBlock(x + 4, y + 3, z + 3, ModBlocks.metadataBlocks, 3, 2);
		world.setBlock(x + 4, y + 3, z + 4, ModBlocks.metadataBlocks, 7, 2);
		world.setBlock(x + 4, y + 3, z + 5, ModBlocks.metadataBlocks, 7, 2);
		world.setBlock(x + 4, y + 3, z + 6, ModBlocks.metadataBlocks, 7, 2);
		world.setBlock(x + 4, y + 3, z + 7, ModBlocks.metadataBlocks, 3, 2);
		world.setBlock(x + 4, y + 3, z + 8, ModBlocks.metadataBlocks, 3, 2);
		world.setBlock(x + 4, y + 3, z + 10, Blocks.obsidian);
		world.setBlock(x + 4, y + 4, z + 0, Blocks.obsidian);
		world.setBlock(x + 4, y + 4, z + 1, ModBlocks.metadataBlocks, 3, 2);
		world.setBlock(x + 4, y + 4, z + 2, ModBlocks.metadataBlocks, 3, 2);
		world.setBlock(x + 4, y + 4, z + 3, ModBlocks.metadataBlocks, 7, 2);
		world.setBlock(x + 4, y + 4, z + 4, ModBlocks.metadataBlocks, 7, 2);
		world.setBlock(x + 4, y + 4, z + 5, ModBlocks.metadataBlocks, 7, 2);
		world.setBlock(x + 4, y + 4, z + 6, ModBlocks.metadataBlocks, 7, 2);
		world.setBlock(x + 4, y + 4, z + 7, ModBlocks.metadataBlocks, 3, 2);
		world.setBlock(x + 4, y + 4, z + 8, ModBlocks.metadataBlocks, 7, 2);
		world.setBlock(x + 4, y + 4, z + 9, ModBlocks.metadataBlocks, 7, 2);
		world.setBlock(x + 4, y + 4, z + 10, ModBlocks.metadataBlocks, 3, 2);
		world.setBlock(x + 4, y + 5, z + 0, Blocks.obsidian);
		world.setBlock(x + 4, y + 5, z + 1, ModBlocks.metadataBlocks, 3, 2);
		world.setBlock(x + 4, y + 5, z + 2, ModBlocks.metadataBlocks, 7, 2);
		world.setBlock(x + 4, y + 5, z + 3, ModBlocks.metadataBlocks, 7, 2);
		world.setBlock(x + 4, y + 5, z + 4, ModBlocks.metadataBlocks, 7, 2);
		world.setBlock(x + 4, y + 5, z + 5, ModBlocks.metadataBlocks, 7, 2);
		world.setBlock(x + 4, y + 5, z + 6, ModBlocks.metadataBlocks, 7, 2);
		world.setBlock(x + 4, y + 5, z + 7, ModBlocks.metadataBlocks, 7, 2);
		world.setBlock(x + 4, y + 5, z + 8, ModBlocks.metadataBlocks, 7, 2);
		world.setBlock(x + 4, y + 5, z + 9, ModBlocks.metadataBlocks, 3, 2);
		world.setBlock(x + 4, y + 5, z + 10, ModBlocks.metadataBlocks, 7, 2);
		world.setBlock(x + 4, y + 6, z + 0, Blocks.obsidian);
		world.setBlock(x + 4, y + 6, z + 1, ModBlocks.metadataBlocks, 7, 2);
		world.setBlock(x + 4, y + 6, z + 2, ModBlocks.metadataBlocks, 7, 2);
		world.setBlock(x + 4, y + 6, z + 3, ModBlocks.metadataBlocks, 7, 2);
		world.setBlock(x + 4, y + 6, z + 4, ModBlocks.metadataBlocks, 3, 2);
		world.setBlock(x + 4, y + 6, z + 5, ModBlocks.metadataBlocks, 3, 2);
		world.setBlock(x + 4, y + 6, z + 6, ModBlocks.metadataBlocks, 7, 2);
		world.setBlock(x + 4, y + 6, z + 7, ModBlocks.metadataBlocks, 7, 2);
		world.setBlock(x + 4, y + 6, z + 8, ModBlocks.metadataBlocks, 7, 2);
		world.setBlock(x + 4, y + 6, z + 9, ModBlocks.metadataBlocks, 7, 2);
		world.setBlock(x + 4, y + 6, z + 10, ModBlocks.metadataBlocks, 7, 2);
		world.setBlock(x + 4, y + 7, z + 0, Blocks.obsidian);
		world.setBlock(x + 4, y + 7, z + 1, ModBlocks.metadataBlocks, 7, 2);
		world.setBlock(x + 4, y + 7, z + 2, ModBlocks.metadataBlocks, 7, 2);
		world.setBlock(x + 4, y + 7, z + 3, ModBlocks.metadataBlocks, 3, 2);
		world.setBlock(x + 4, y + 7, z + 4, ModBlocks.metadataBlocks, 7, 2);
		world.setBlock(x + 4, y + 7, z + 5, ModBlocks.metadataBlocks, 3, 2);
		world.setBlock(x + 4, y + 7, z + 6, ModBlocks.metadataBlocks, 7, 2);
		world.setBlock(x + 4, y + 7, z + 7, ModBlocks.metadataBlocks, 3, 2);
		world.setBlock(x + 4, y + 7, z + 8, ModBlocks.metadataBlocks, 7, 2);
		world.setBlock(x + 4, y + 7, z + 9, ModBlocks.metadataBlocks, 7, 2);
		world.setBlock(x + 4, y + 7, z + 10, ModBlocks.metadataBlocks, 3, 2);
		world.setBlock(x + 4, y + 8, z + 1, Blocks.obsidian);
		world.setBlock(x + 4, y + 8, z + 2, ModBlocks.metadataBlocks, 7, 2);
		world.setBlock(x + 4, y + 8, z + 3, ModBlocks.metadataBlocks, 7, 2);
		world.setBlock(x + 4, y + 8, z + 4, ModBlocks.metadataBlocks, 7, 2);
		world.setBlock(x + 4, y + 8, z + 5, ModBlocks.metadataBlocks, 7, 2);
		world.setBlock(x + 4, y + 8, z + 6, ModBlocks.metadataBlocks, 7, 2);
		world.setBlock(x + 4, y + 8, z + 7, ModBlocks.metadataBlocks, 7, 2);
		world.setBlock(x + 4, y + 8, z + 8, ModBlocks.metadataBlocks, 7, 2);
		world.setBlock(x + 4, y + 8, z + 9, Blocks.obsidian);
		world.setBlock(x + 4, y + 9, z + 2, Blocks.obsidian);
		world.setBlock(x + 4, y + 9, z + 3, ModBlocks.metadataBlocks, 7, 2);
		world.setBlock(x + 4, y + 9, z + 4, ModBlocks.metadataBlocks, 7, 2);
		world.setBlock(x + 4, y + 9, z + 5, ModBlocks.metadataBlocks, 7, 2);
		world.setBlock(x + 4, y + 9, z + 6, ModBlocks.metadataBlocks, 7, 2);
		world.setBlock(x + 4, y + 9, z + 7, ModBlocks.metadataBlocks, 2, 2);
		world.setBlock(x + 4, y + 9, z + 8, ModBlocks.metadataBlocks, 7, 2);
		world.setBlock(x + 4, y + 10, z + 3, ModBlocks.metadataBlocks, 3, 2);
		world.setBlock(x + 4, y + 10, z + 4, Blocks.obsidian);
		world.setBlock(x + 4, y + 10, z + 5, Blocks.obsidian);
		world.setBlock(x + 4, y + 10, z + 6, Blocks.obsidian);
		world.setBlock(x + 4, y + 10, z + 7, Blocks.obsidian);
		world.setBlock(x + 5, y + 0, z + 3, Blocks.obsidian);
		world.setBlock(x + 5, y + 0, z + 4, Blocks.obsidian);
		world.setBlock(x + 5, y + 0, z + 5, ModBlocks.metadataBlocks, 7, 2);
		world.setBlock(x + 5, y + 0, z + 6, ModBlocks.metadataBlocks, 7, 2);
		world.setBlock(x + 5, y + 0, z + 7, ModBlocks.metadataBlocks, 7, 2);
		world.setBlock(x + 5, y + 1, z + 2, Blocks.obsidian);
		world.setBlock(x + 5, y + 1, z + 3, ModBlocks.metadataBlocks, 2, 2);
		world.setBlock(x + 5, y + 1, z + 4, ModBlocks.metadataBlocks, 3, 2);
		world.setBlock(x + 5, y + 1, z + 5, ModBlocks.metadataBlocks, 7, 2);
		world.setBlock(x + 5, y + 1, z + 6, ModBlocks.metadataBlocks, 7, 2);
		world.setBlock(x + 5, y + 1, z + 7, ModBlocks.metadataBlocks, 7, 2);
		world.setBlock(x + 5, y + 1, z + 8, Blocks.obsidian);
		world.setBlock(x + 5, y + 2, z + 1, Blocks.obsidian);
		world.setBlock(x + 5, y + 2, z + 2, ModBlocks.metadataBlocks, 3, 2);
		world.setBlock(x + 5, y + 2, z + 3, ModBlocks.metadataBlocks, 3, 2);
		world.setBlock(x + 5, y + 2, z + 4, ModBlocks.metadataBlocks, 3, 2);
		world.setBlock(x + 5, y + 2, z + 5, ModBlocks.metadataBlocks, 7, 2);
		world.setBlock(x + 5, y + 2, z + 6, ModBlocks.metadataBlocks, 7, 2);
		world.setBlock(x + 5, y + 2, z + 7, ModBlocks.metadataBlocks, 7, 2);
		world.setBlock(x + 5, y + 2, z + 8, ModBlocks.metadataBlocks, 3, 2);
		world.setBlock(x + 5, y + 2, z + 9, ModBlocks.metadataBlocks, 3, 2);
		world.setBlock(x + 5, y + 2, z + 10, ModBlocks.metadataBlocks, 7, 2);
		world.setBlock(x + 5, y + 3, z + 0, Blocks.obsidian);
		world.setBlock(x + 5, y + 3, z + 1, ModBlocks.metadataBlocks, 3, 2);
		world.setBlock(x + 5, y + 3, z + 2, ModBlocks.metadataBlocks, 3, 2);
		world.setBlock(x + 5, y + 3, z + 3, ModBlocks.metadataBlocks, 3, 2);
		world.setBlock(x + 5, y + 3, z + 4, ModBlocks.metadataBlocks, 3, 2);
		world.setBlock(x + 5, y + 3, z + 5, ModBlocks.metadataBlocks, 7, 2);
		world.setBlock(x + 5, y + 3, z + 6, ModBlocks.metadataBlocks, 7, 2);
		world.setBlock(x + 5, y + 3, z + 7, ModBlocks.metadataBlocks, 7, 2);
		world.setBlock(x + 5, y + 3, z + 8, ModBlocks.metadataBlocks, 7, 2);
		world.setBlock(x + 5, y + 3, z + 9, ModBlocks.metadataBlocks, 7, 2);
		world.setBlock(x + 5, y + 3, z + 10, ModBlocks.metadataBlocks, 3, 2);
		world.setBlock(x + 5, y + 4, z + 0, Blocks.obsidian);
		world.setBlock(x + 5, y + 4, z + 1, ModBlocks.metadataBlocks, 3, 2);
		world.setBlock(x + 5, y + 4, z + 2, ModBlocks.metadataBlocks, 3, 2);
		world.setBlock(x + 5, y + 4, z + 3, ModBlocks.metadataBlocks, 2, 2);
		world.setBlock(x + 5, y + 4, z + 4, ModBlocks.metadataBlocks, 7, 2);
		world.setBlock(x + 5, y + 4, z + 5, ModBlocks.metadataBlocks, 7, 2);
		world.setBlock(x + 5, y + 4, z + 6, ModBlocks.metadataBlocks, 7, 2);
		world.setBlock(x + 5, y + 4, z + 7, ModBlocks.metadataBlocks, 7, 2);
		world.setBlock(x + 5, y + 4, z + 8, ModBlocks.metadataBlocks, 7, 2);
		world.setBlock(x + 5, y + 4, z + 9, ModBlocks.metadataBlocks, 7, 2);
		world.setBlock(x + 5, y + 4, z + 10, ModBlocks.metadataBlocks, 7, 2);
		world.setBlock(x + 5, y + 5, z + 0, Blocks.obsidian);
		world.setBlock(x + 5, y + 5, z + 1, ModBlocks.metadataBlocks, 3, 2);
		world.setBlock(x + 5, y + 5, z + 2, ModBlocks.metadataBlocks, 3, 2);
		world.setBlock(x + 5, y + 5, z + 3, ModBlocks.metadataBlocks, 7, 2);
		world.setBlock(x + 5, y + 5, z + 4, ModBlocks.metadataBlocks, 7, 2);
		world.setBlock(x + 5, y + 5, z + 5, ModBlocks.metadataBlocks, 7, 2);
		world.setBlock(x + 5, y + 5, z + 6, ModBlocks.metadataBlocks, 7, 2);
		world.setBlock(x + 5, y + 5, z + 7, ModBlocks.metadataBlocks, 3, 2);
		world.setBlock(x + 5, y + 5, z + 8, ModBlocks.metadataBlocks, 7, 2);
		world.setBlock(x + 5, y + 5, z + 9, ModBlocks.metadataBlocks, 7, 2);
		world.setBlock(x + 5, y + 5, z + 10, ModBlocks.metadataBlocks, 7, 2);
		world.setBlock(x + 5, y + 6, z + 0, Blocks.obsidian);
		world.setBlock(x + 5, y + 6, z + 1, ModBlocks.metadataBlocks, 7, 2);
		world.setBlock(x + 5, y + 6, z + 2, ModBlocks.metadataBlocks, 7, 2);
		world.setBlock(x + 5, y + 6, z + 3, ModBlocks.metadataBlocks, 7, 2);
		world.setBlock(x + 5, y + 6, z + 4, ModBlocks.metadataBlocks, 7, 2);
		world.setBlock(x + 5, y + 6, z + 5, ModBlocks.metadataBlocks, 7, 2);
		world.setBlock(x + 5, y + 6, z + 6, ModBlocks.metadataBlocks, 7, 2);
		world.setBlock(x + 5, y + 6, z + 7, ModBlocks.metadataBlocks, 7, 2);
		world.setBlock(x + 5, y + 6, z + 8, ModBlocks.metadataBlocks, 7, 2);
		world.setBlock(x + 5, y + 6, z + 9, ModBlocks.metadataBlocks, 7, 2);
		world.setBlock(x + 5, y + 6, z + 10, Blocks.obsidian);
		world.setBlock(x + 5, y + 7, z + 0, Blocks.obsidian);
		world.setBlock(x + 5, y + 7, z + 1, ModBlocks.metadataBlocks, 7, 2);
		world.setBlock(x + 5, y + 7, z + 2, ModBlocks.metadataBlocks, 7, 2);
		world.setBlock(x + 5, y + 7, z + 3, ModBlocks.metadataBlocks, 7, 2);
		world.setBlock(x + 5, y + 7, z + 4, ModBlocks.metadataBlocks, 7, 2);
		world.setBlock(x + 5, y + 7, z + 5, ModBlocks.metadataBlocks, 7, 2);
		world.setBlock(x + 5, y + 7, z + 6, ModBlocks.metadataBlocks, 7, 2);
		world.setBlock(x + 5, y + 7, z + 7, ModBlocks.metadataBlocks, 7, 2);
		world.setBlock(x + 5, y + 7, z + 8, ModBlocks.metadataBlocks, 3, 2);
		world.setBlock(x + 5, y + 7, z + 9, ModBlocks.metadataBlocks, 3, 2);
		world.setBlock(x + 5, y + 7, z + 10, Blocks.obsidian);
		world.setBlock(x + 5, y + 8, z + 1, Blocks.obsidian);
		world.setBlock(x + 5, y + 8, z + 2, ModBlocks.metadataBlocks, 7, 2);
		world.setBlock(x + 5, y + 8, z + 3, ModBlocks.metadataBlocks, 7, 2);
		world.setBlock(x + 5, y + 8, z + 4, ModBlocks.metadataBlocks, 7, 2);
		world.setBlock(x + 5, y + 8, z + 5, ModBlocks.metadataBlocks, 7, 2);
		world.setBlock(x + 5, y + 8, z + 6, ModBlocks.metadataBlocks, 3, 2);
		world.setBlock(x + 5, y + 8, z + 7, ModBlocks.metadataBlocks, 3, 2);
		world.setBlock(x + 5, y + 8, z + 8, ModBlocks.metadataBlocks, 3, 2);
		world.setBlock(x + 5, y + 8, z + 9, Blocks.obsidian);
		world.setBlock(x + 5, y + 9, z + 2, Blocks.obsidian);
		world.setBlock(x + 5, y + 9, z + 3, ModBlocks.metadataBlocks, 7, 2);
		world.setBlock(x + 5, y + 9, z + 4, ModBlocks.metadataBlocks, 7, 2);
		world.setBlock(x + 5, y + 9, z + 5, ModBlocks.metadataBlocks, 7, 2);
		world.setBlock(x + 5, y + 9, z + 6, ModBlocks.metadataBlocks, 2, 2);
		world.setBlock(x + 5, y + 9, z + 7, ModBlocks.metadataBlocks, 7, 2);
		world.setBlock(x + 5, y + 9, z + 8, Blocks.obsidian);
		world.setBlock(x + 5, y + 10, z + 3, Blocks.obsidian);
		world.setBlock(x + 5, y + 10, z + 4, ModBlocks.metadataBlocks, 3, 2);
		world.setBlock(x + 5, y + 10, z + 5, Blocks.obsidian);
		world.setBlock(x + 5, y + 10, z + 6, Blocks.obsidian);
		world.setBlock(x + 5, y + 10, z + 7, Blocks.obsidian);
		world.setBlock(x + 6, y + 0, z + 3, ModBlocks.metadataBlocks, 7, 2);
		world.setBlock(x + 6, y + 0, z + 4, ModBlocks.metadataBlocks, 7, 2);
		world.setBlock(x + 6, y + 0, z + 5, ModBlocks.metadataBlocks, 3, 2);
		world.setBlock(x + 6, y + 0, z + 6, ModBlocks.metadataBlocks, 7, 2);
		world.setBlock(x + 6, y + 0, z + 7, ModBlocks.metadataBlocks, 7, 2);
		world.setBlock(x + 6, y + 0, z + 8, ModBlocks.metadataBlocks, 7, 2);
		world.setBlock(x + 6, y + 1, z + 2, Blocks.obsidian);
		world.setBlock(x + 6, y + 1, z + 3, ModBlocks.metadataBlocks, 7, 2);
		world.setBlock(x + 6, y + 1, z + 4, ModBlocks.metadataBlocks, 7, 2);
		world.setBlock(x + 6, y + 1, z + 5, ModBlocks.metadataBlocks, 7, 2);
		world.setBlock(x + 6, y + 1, z + 6, ModBlocks.metadataBlocks, 7, 2);
		world.setBlock(x + 6, y + 1, z + 7, ModBlocks.metadataBlocks, 7, 2);
		world.setBlock(x + 6, y + 1, z + 8, ModBlocks.metadataBlocks, 7, 2);
		world.setBlock(x + 6, y + 1, z + 9, ModBlocks.metadataBlocks, 7, 2);
		world.setBlock(x + 6, y + 2, z + 1, Blocks.obsidian);
		world.setBlock(x + 6, y + 2, z + 2, ModBlocks.metadataBlocks, 3, 2);
		world.setBlock(x + 6, y + 2, z + 3, ModBlocks.metadataBlocks, 3, 2);
		world.setBlock(x + 6, y + 2, z + 4, ModBlocks.metadataBlocks, 7, 2);
		world.setBlock(x + 6, y + 2, z + 5, ModBlocks.metadataBlocks, 7, 2);
		world.setBlock(x + 6, y + 2, z + 6, ModBlocks.metadataBlocks, 3, 2);
		world.setBlock(x + 6, y + 2, z + 7, ModBlocks.metadataBlocks, 7, 2);
		world.setBlock(x + 6, y + 2, z + 8, ModBlocks.metadataBlocks, 7, 2);
		world.setBlock(x + 6, y + 2, z + 9, ModBlocks.metadataBlocks, 7, 2);
		world.setBlock(x + 6, y + 2, z + 10, ModBlocks.metadataBlocks, 7, 2);
		world.setBlock(x + 6, y + 3, z + 0, Blocks.obsidian);
		world.setBlock(x + 6, y + 3, z + 2, ModBlocks.metadataBlocks, 3, 2);
		world.setBlock(x + 6, y + 3, z + 3, ModBlocks.metadataBlocks, 3, 2);
		world.setBlock(x + 6, y + 3, z + 4, ModBlocks.metadataBlocks, 7, 2);
		world.setBlock(x + 6, y + 3, z + 5, ModBlocks.metadataBlocks, 7, 2);
		world.setBlock(x + 6, y + 3, z + 6, ModBlocks.metadataBlocks, 7, 2);
		world.setBlock(x + 6, y + 3, z + 7, ModBlocks.metadataBlocks, 7, 2);
		world.setBlock(x + 6, y + 3, z + 8, ModBlocks.metadataBlocks, 7, 2);
		world.setBlock(x + 6, y + 3, z + 9, ModBlocks.metadataBlocks, 7, 2);
		world.setBlock(x + 6, y + 3, z + 10, ModBlocks.metadataBlocks, 7, 2);
		world.setBlock(x + 6, y + 4, z + 0, Blocks.obsidian);
		world.setBlock(x + 6, y + 4, z + 1, ModBlocks.metadataBlocks, 7, 2);
		world.setBlock(x + 6, y + 4, z + 2, ModBlocks.metadataBlocks, 3, 2);
		world.setBlock(x + 6, y + 4, z + 3, ModBlocks.metadataBlocks, 7, 2);
		world.setBlock(x + 6, y + 4, z + 4, ModBlocks.metadataBlocks, 7, 2);
		world.setBlock(x + 6, y + 4, z + 5, ModBlocks.metadataBlocks, 7, 2);
		world.setBlock(x + 6, y + 4, z + 6, ModBlocks.metadataBlocks, 7, 2);
		world.setBlock(x + 6, y + 4, z + 7, ModBlocks.metadataBlocks, 3, 2);
		world.setBlock(x + 6, y + 4, z + 8, ModBlocks.metadataBlocks, 7, 2);
		world.setBlock(x + 6, y + 4, z + 9, ModBlocks.metadataBlocks, 7, 2);
		world.setBlock(x + 6, y + 4, z + 10, ModBlocks.metadataBlocks, 7, 2);
		world.setBlock(x + 6, y + 5, z + 0, Blocks.obsidian);
		world.setBlock(x + 6, y + 5, z + 1, ModBlocks.metadataBlocks, 7, 2);
		world.setBlock(x + 6, y + 5, z + 2, ModBlocks.metadataBlocks, 7, 2);
		world.setBlock(x + 6, y + 5, z + 3, ModBlocks.metadataBlocks, 7, 2);
		world.setBlock(x + 6, y + 5, z + 4, ModBlocks.metadataBlocks, 7, 2);
		world.setBlock(x + 6, y + 5, z + 5, ModBlocks.metadataBlocks, 7, 2);
		world.setBlock(x + 6, y + 5, z + 6, ModBlocks.metadataBlocks, 7, 2);
		world.setBlock(x + 6, y + 5, z + 7, ModBlocks.metadataBlocks, 3, 2);
		world.setBlock(x + 6, y + 5, z + 8, ModBlocks.metadataBlocks, 3, 2);
		world.setBlock(x + 6, y + 5, z + 9, ModBlocks.metadataBlocks, 3, 2);
		world.setBlock(x + 6, y + 5, z + 10, Blocks.obsidian);
		world.setBlock(x + 6, y + 6, z + 0, Blocks.obsidian);
		world.setBlock(x + 6, y + 6, z + 1, ModBlocks.metadataBlocks, 7, 2);
		world.setBlock(x + 6, y + 6, z + 2, ModBlocks.metadataBlocks, 7, 2);
		world.setBlock(x + 6, y + 6, z + 3, ModBlocks.metadataBlocks, 7, 2);
		world.setBlock(x + 6, y + 6, z + 4, ModBlocks.metadataBlocks, 7, 2);
		world.setBlock(x + 6, y + 6, z + 5, ModBlocks.metadataBlocks, 7, 2);
		world.setBlock(x + 6, y + 6, z + 6, ModBlocks.metadataBlocks, 7, 2);
		world.setBlock(x + 6, y + 6, z + 7, ModBlocks.metadataBlocks, 3, 2);
		world.setBlock(x + 6, y + 6, z + 8, ModBlocks.metadataBlocks, 3, 2);
		world.setBlock(x + 6, y + 6, z + 9, ModBlocks.metadataBlocks, 3, 2);
		world.setBlock(x + 6, y + 6, z + 10, ModBlocks.metadataBlocks, 3, 2);
		world.setBlock(x + 6, y + 7, z + 0, Blocks.obsidian);
		world.setBlock(x + 6, y + 7, z + 1, ModBlocks.metadataBlocks, 7, 2);
		world.setBlock(x + 6, y + 7, z + 2, ModBlocks.metadataBlocks, 7, 2);
		world.setBlock(x + 6, y + 7, z + 3, ModBlocks.metadataBlocks, 7, 2);
		world.setBlock(x + 6, y + 7, z + 4, ModBlocks.metadataBlocks, 7, 2);
		world.setBlock(x + 6, y + 7, z + 5, ModBlocks.metadataBlocks, 7, 2);
		world.setBlock(x + 6, y + 7, z + 6, ModBlocks.metadataBlocks, 7, 2);
		world.setBlock(x + 6, y + 7, z + 7, ModBlocks.metadataBlocks, 3, 2);
		world.setBlock(x + 6, y + 7, z + 8, ModBlocks.metadataBlocks, 3, 2);
		world.setBlock(x + 6, y + 7, z + 10, Blocks.obsidian);
		world.setBlock(x + 6, y + 8, z + 1, ModBlocks.metadataBlocks, 3, 2);
		world.setBlock(x + 6, y + 8, z + 2, ModBlocks.metadataBlocks, 3, 2);
		world.setBlock(x + 6, y + 8, z + 3, ModBlocks.metadataBlocks, 7, 2);
		world.setBlock(x + 6, y + 8, z + 4, ModBlocks.metadataBlocks, 7, 2);
		world.setBlock(x + 6, y + 8, z + 5, ModBlocks.metadataBlocks, 7, 2);
		world.setBlock(x + 6, y + 8, z + 6, ModBlocks.metadataBlocks, 7, 2);
		world.setBlock(x + 6, y + 8, z + 7, ModBlocks.metadataBlocks, 3, 2);
		world.setBlock(x + 6, y + 8, z + 8, ModBlocks.metadataBlocks, 3, 2);
		world.setBlock(x + 6, y + 8, z + 9, Blocks.obsidian);
		world.setBlock(x + 6, y + 9, z + 2, Blocks.obsidian);
		world.setBlock(x + 6, y + 9, z + 3, ModBlocks.metadataBlocks, 7, 2);
		world.setBlock(x + 6, y + 9, z + 4, ModBlocks.metadataBlocks, 7, 2);
		world.setBlock(x + 6, y + 9, z + 5, ModBlocks.metadataBlocks, 7, 2);
		world.setBlock(x + 6, y + 9, z + 6, ModBlocks.metadataBlocks, 3, 2);
		world.setBlock(x + 6, y + 9, z + 7, ModBlocks.metadataBlocks, 3, 2);
		world.setBlock(x + 6, y + 9, z + 8, Blocks.obsidian);
		world.setBlock(x + 6, y + 10, z + 3, Blocks.obsidian);
		world.setBlock(x + 6, y + 10, z + 4, Blocks.obsidian);
		world.setBlock(x + 6, y + 10, z + 5, Blocks.obsidian);
		world.setBlock(x + 6, y + 10, z + 6, Blocks.obsidian);
		world.setBlock(x + 6, y + 10, z + 7, Blocks.obsidian);
		world.setBlock(x + 7, y + 0, z + 3, ModBlocks.metadataBlocks, 7, 2);
		world.setBlock(x + 7, y + 0, z + 4, ModBlocks.metadataBlocks, 7, 2);
		world.setBlock(x + 7, y + 0, z + 5, ModBlocks.metadataBlocks, 7, 2);
		world.setBlock(x + 7, y + 0, z + 6, Blocks.obsidian);
		world.setBlock(x + 7, y + 0, z + 7, ModBlocks.metadataBlocks, 7, 2);
		world.setBlock(x + 7, y + 0, z + 8, ModBlocks.metadataBlocks, 7, 2);
		world.setBlock(x + 7, y + 1, z + 2, ModBlocks.metadataBlocks, 7, 2);
		world.setBlock(x + 7, y + 1, z + 3, ModBlocks.metadataBlocks, 7, 2);
		world.setBlock(x + 7, y + 1, z + 4, ModBlocks.metadataBlocks, 7, 2);
		world.setBlock(x + 7, y + 1, z + 5, ModBlocks.metadataBlocks, 7, 2);
		world.setBlock(x + 7, y + 1, z + 7, ModBlocks.metadataBlocks, 7, 2);
		world.setBlock(x + 7, y + 1, z + 8, ModBlocks.metadataBlocks, 2, 2);
		world.setBlock(x + 7, y + 1, z + 9, ModBlocks.metadataBlocks, 7, 2);
		world.setBlock(x + 7, y + 2, z + 1, Blocks.obsidian);
		world.setBlock(x + 7, y + 2, z + 2, ModBlocks.metadataBlocks, 7, 2);
		world.setBlock(x + 7, y + 2, z + 3, ModBlocks.metadataBlocks, 7, 2);
		world.setBlock(x + 7, y + 2, z + 4, ModBlocks.metadataBlocks, 7, 2);
		world.setBlock(x + 7, y + 2, z + 5, ModBlocks.metadataBlocks, 7, 2);
		world.setBlock(x + 7, y + 2, z + 6, ModBlocks.metadataBlocks, 2, 2);
		world.setBlock(x + 7, y + 2, z + 7, ModBlocks.metadataBlocks, 7, 2);
		world.setBlock(x + 7, y + 2, z + 8, ModBlocks.metadataBlocks, 3, 2);
		world.setBlock(x + 7, y + 2, z + 9, ModBlocks.metadataBlocks, 7, 2);
		world.setBlock(x + 7, y + 2, z + 10, ModBlocks.metadataBlocks, 7, 2);
		world.setBlock(x + 7, y + 3, z + 1, ModBlocks.metadataBlocks, 7, 2);
		world.setBlock(x + 7, y + 3, z + 2, ModBlocks.metadataBlocks, 7, 2);
		world.setBlock(x + 7, y + 3, z + 3, ModBlocks.metadataBlocks, 7, 2);
		world.setBlock(x + 7, y + 3, z + 4, ModBlocks.metadataBlocks, 7, 2);
		world.setBlock(x + 7, y + 3, z + 5, ModBlocks.metadataBlocks, 7, 2);
		world.setBlock(x + 7, y + 3, z + 6, ModBlocks.metadataBlocks, 3, 2);
		world.setBlock(x + 7, y + 3, z + 7, ModBlocks.metadataBlocks, 7, 2);
		world.setBlock(x + 7, y + 3, z + 8, ModBlocks.metadataBlocks, 7, 2);
		world.setBlock(x + 7, y + 3, z + 9, ModBlocks.metadataBlocks, 7, 2);
		world.setBlock(x + 7, y + 4, z + 0, Blocks.obsidian);
		world.setBlock(x + 7, y + 4, z + 1, ModBlocks.metadataBlocks, 3, 2);
		world.setBlock(x + 7, y + 4, z + 2, ModBlocks.metadataBlocks, 7, 2);
		world.setBlock(x + 7, y + 4, z + 3, ModBlocks.metadataBlocks, 7, 2);
		world.setBlock(x + 7, y + 4, z + 4, ModBlocks.metadataBlocks, 7, 2);
		world.setBlock(x + 7, y + 4, z + 5, ModBlocks.metadataBlocks, 7, 2);
		world.setBlock(x + 7, y + 4, z + 6, ModBlocks.metadataBlocks, 7, 2);
		world.setBlock(x + 7, y + 4, z + 7, ModBlocks.metadataBlocks, 7, 2);
		world.setBlock(x + 7, y + 4, z + 8, ModBlocks.metadataBlocks, 7, 2);
		world.setBlock(x + 7, y + 4, z + 10, Blocks.obsidian);
		world.setBlock(x + 7, y + 5, z + 0, ModBlocks.metadataBlocks, 3, 2);
		world.setBlock(x + 7, y + 5, z + 1, ModBlocks.metadataBlocks, 7, 2);
		world.setBlock(x + 7, y + 5, z + 2, ModBlocks.metadataBlocks, 7, 2);
		world.setBlock(x + 7, y + 5, z + 3, ModBlocks.metadataBlocks, 7, 2);
		world.setBlock(x + 7, y + 5, z + 4, ModBlocks.metadataBlocks, 3, 2);
		world.setBlock(x + 7, y + 5, z + 5, ModBlocks.metadataBlocks, 7, 2);
		world.setBlock(x + 7, y + 5, z + 6, ModBlocks.metadataBlocks, 7, 2);
		world.setBlock(x + 7, y + 5, z + 7, ModBlocks.metadataBlocks, 7, 2);
		world.setBlock(x + 7, y + 5, z + 8, ModBlocks.metadataBlocks, 3, 2);
		world.setBlock(x + 7, y + 5, z + 9, ModBlocks.metadataBlocks, 3, 2);
		world.setBlock(x + 7, y + 5, z + 10, Blocks.obsidian);
		world.setBlock(x + 7, y + 6, z + 0, Blocks.obsidian);
		world.setBlock(x + 7, y + 6, z + 1, ModBlocks.metadataBlocks, 7, 2);
		world.setBlock(x + 7, y + 6, z + 2, ModBlocks.metadataBlocks, 7, 2);
		world.setBlock(x + 7, y + 6, z + 3, ModBlocks.metadataBlocks, 3, 2);
		world.setBlock(x + 7, y + 6, z + 4, ModBlocks.metadataBlocks, 3, 2);
		world.setBlock(x + 7, y + 6, z + 5, ModBlocks.metadataBlocks, 7, 2);
		world.setBlock(x + 7, y + 6, z + 6, ModBlocks.metadataBlocks, 7, 2);
		world.setBlock(x + 7, y + 6, z + 7, ModBlocks.metadataBlocks, 7, 2);
		world.setBlock(x + 7, y + 6, z + 8, ModBlocks.metadataBlocks, 3, 2);
		world.setBlock(x + 7, y + 6, z + 10, Blocks.obsidian);
		world.setBlock(x + 7, y + 7, z + 1, ModBlocks.metadataBlocks, 3, 2);
		world.setBlock(x + 7, y + 7, z + 2, ModBlocks.metadataBlocks, 3, 2);
		world.setBlock(x + 7, y + 7, z + 3, ModBlocks.metadataBlocks, 3, 2);
		world.setBlock(x + 7, y + 7, z + 4, ModBlocks.metadataBlocks, 3, 2);
		world.setBlock(x + 7, y + 7, z + 5, ModBlocks.metadataBlocks, 7, 2);
		world.setBlock(x + 7, y + 7, z + 6, ModBlocks.metadataBlocks, 2, 2);
		world.setBlock(x + 7, y + 7, z + 7, ModBlocks.metadataBlocks, 7, 2);
		world.setBlock(x + 7, y + 7, z + 8, ModBlocks.metadataBlocks, 3, 2);
		world.setBlock(x + 7, y + 7, z + 9, ModBlocks.metadataBlocks, 3, 2);
		world.setBlock(x + 7, y + 8, z + 1, Blocks.obsidian);
		world.setBlock(x + 7, y + 8, z + 3, ModBlocks.metadataBlocks, 3, 2);
		world.setBlock(x + 7, y + 8, z + 4, ModBlocks.metadataBlocks, 3, 2);
		world.setBlock(x + 7, y + 8, z + 5, ModBlocks.metadataBlocks, 7, 2);
		world.setBlock(x + 7, y + 8, z + 6, ModBlocks.metadataBlocks, 7, 2);
		world.setBlock(x + 7, y + 8, z + 7, ModBlocks.metadataBlocks, 3, 2);
		world.setBlock(x + 7, y + 8, z + 9, Blocks.obsidian);
		world.setBlock(x + 7, y + 9, z + 2, Blocks.obsidian);
		world.setBlock(x + 7, y + 9, z + 3, Blocks.obsidian);
		world.setBlock(x + 7, y + 9, z + 5, ModBlocks.metadataBlocks, 3, 2);
		world.setBlock(x + 7, y + 9, z + 6, ModBlocks.metadataBlocks, 7, 2);
		world.setBlock(x + 7, y + 9, z + 7, ModBlocks.metadataBlocks, 7, 2);
		world.setBlock(x + 7, y + 9, z + 8, Blocks.obsidian);
		world.setBlock(x + 7, y + 10, z + 4, Blocks.obsidian);
		world.setBlock(x + 7, y + 10, z + 5, Blocks.obsidian);
		world.setBlock(x + 7, y + 10, z + 6, ModBlocks.metadataBlocks, 2, 2);
		world.setBlock(x + 8, y + 0, z + 4, ModBlocks.metadataBlocks, 7, 2);
		world.setBlock(x + 8, y + 1, z + 2, ModBlocks.metadataBlocks, 7, 2);
		world.setBlock(x + 8, y + 1, z + 3, ModBlocks.metadataBlocks, 7, 2);
		world.setBlock(x + 8, y + 1, z + 4, ModBlocks.metadataBlocks, 7, 2);
		world.setBlock(x + 8, y + 1, z + 5, ModBlocks.metadataBlocks, 7, 2);
		world.setBlock(x + 8, y + 1, z + 6, Blocks.obsidian);
		world.setBlock(x + 8, y + 1, z + 7, Blocks.obsidian);
		world.setBlock(x + 8, y + 1, z + 9, ModBlocks.metadataBlocks, 7, 2);
		world.setBlock(x + 8, y + 2, z + 2, ModBlocks.metadataBlocks, 7, 2);
		world.setBlock(x + 8, y + 2, z + 3, ModBlocks.metadataBlocks, 7, 2);
		world.setBlock(x + 8, y + 2, z + 4, ModBlocks.metadataBlocks, 7, 2);
		world.setBlock(x + 8, y + 2, z + 5, ModBlocks.metadataBlocks, 3, 2);
		world.setBlock(x + 8, y + 2, z + 6, ModBlocks.metadataBlocks, 3, 2);
		world.setBlock(x + 8, y + 2, z + 8, ModBlocks.metadataBlocks, 7, 2);
		world.setBlock(x + 8, y + 2, z + 9, ModBlocks.metadataBlocks, 7, 2);
		world.setBlock(x + 8, y + 2, z + 10, ModBlocks.metadataBlocks, 7, 2);
		world.setBlock(x + 8, y + 3, z + 1, ModBlocks.metadataBlocks, 7, 2);
		world.setBlock(x + 8, y + 3, z + 2, ModBlocks.metadataBlocks, 7, 2);
		world.setBlock(x + 8, y + 3, z + 3, ModBlocks.metadataBlocks, 7, 2);
		world.setBlock(x + 8, y + 3, z + 4, ModBlocks.metadataBlocks, 7, 2);
		world.setBlock(x + 8, y + 3, z + 5, ModBlocks.metadataBlocks, 3, 2);
		world.setBlock(x + 8, y + 3, z + 6, ModBlocks.metadataBlocks, 3, 2);
		world.setBlock(x + 8, y + 3, z + 7, ModBlocks.metadataBlocks, 3, 2);
		world.setBlock(x + 8, y + 3, z + 8, ModBlocks.metadataBlocks, 7, 2);
		world.setBlock(x + 8, y + 3, z + 9, ModBlocks.metadataBlocks, 7, 2);
		world.setBlock(x + 8, y + 3, z + 10, ModBlocks.metadataBlocks, 7, 2);
		world.setBlock(x + 8, y + 4, z + 1, ModBlocks.metadataBlocks, 7, 2);
		world.setBlock(x + 8, y + 4, z + 2, ModBlocks.metadataBlocks, 7, 2);
		world.setBlock(x + 8, y + 4, z + 3, ModBlocks.metadataBlocks, 7, 2);
		world.setBlock(x + 8, y + 4, z + 4, ModBlocks.metadataBlocks, 7, 2);
		world.setBlock(x + 8, y + 4, z + 5, ModBlocks.metadataBlocks, 7, 2);
		world.setBlock(x + 8, y + 4, z + 6, ModBlocks.metadataBlocks, 3, 2);
		world.setBlock(x + 8, y + 4, z + 7, ModBlocks.metadataBlocks, 7, 2);
		world.setBlock(x + 8, y + 4, z + 8, ModBlocks.metadataBlocks, 7, 2);
		world.setBlock(x + 8, y + 4, z + 9, ModBlocks.metadataBlocks, 7, 2);
		world.setBlock(x + 8, y + 5, z + 1, ModBlocks.metadataBlocks, 7, 2);
		world.setBlock(x + 8, y + 5, z + 2, ModBlocks.metadataBlocks, 3, 2);
		world.setBlock(x + 8, y + 5, z + 3, ModBlocks.metadataBlocks, 2, 2);
		world.setBlock(x + 8, y + 5, z + 4, ModBlocks.metadataBlocks, 7, 2);
		world.setBlock(x + 8, y + 5, z + 5, ModBlocks.metadataBlocks, 7, 2);
		world.setBlock(x + 8, y + 5, z + 6, ModBlocks.metadataBlocks, 3, 2);
		world.setBlock(x + 8, y + 5, z + 7, ModBlocks.metadataBlocks, 7, 2);
		world.setBlock(x + 8, y + 5, z + 8, ModBlocks.metadataBlocks, 2, 2);
		world.setBlock(x + 8, y + 5, z + 9, Blocks.obsidian);
		world.setBlock(x + 8, y + 6, z + 1, Blocks.obsidian);
		world.setBlock(x + 8, y + 6, z + 2, ModBlocks.metadataBlocks, 3, 2);
		world.setBlock(x + 8, y + 6, z + 3, ModBlocks.metadataBlocks, 3, 2);
		world.setBlock(x + 8, y + 6, z + 4, ModBlocks.metadataBlocks, 3, 2);
		world.setBlock(x + 8, y + 6, z + 5, ModBlocks.metadataBlocks, 7, 2);
		world.setBlock(x + 8, y + 6, z + 6, ModBlocks.metadataBlocks, 7, 2);
		world.setBlock(x + 8, y + 6, z + 7, ModBlocks.metadataBlocks, 7, 2);
		world.setBlock(x + 8, y + 6, z + 8, ModBlocks.metadataBlocks, 3, 2);
		world.setBlock(x + 8, y + 6, z + 9, Blocks.obsidian);
		world.setBlock(x + 8, y + 7, z + 1, Blocks.obsidian);
		world.setBlock(x + 8, y + 7, z + 3, ModBlocks.metadataBlocks, 3, 2);
		world.setBlock(x + 8, y + 7, z + 4, ModBlocks.metadataBlocks, 3, 2);
		world.setBlock(x + 8, y + 7, z + 5, ModBlocks.metadataBlocks, 7, 2);
		world.setBlock(x + 8, y + 7, z + 6, ModBlocks.metadataBlocks, 7, 2);
		world.setBlock(x + 8, y + 7, z + 7, ModBlocks.metadataBlocks, 7, 2);
		world.setBlock(x + 8, y + 7, z + 9, Blocks.obsidian);
		world.setBlock(x + 8, y + 8, z + 2, Blocks.obsidian);
		world.setBlock(x + 8, y + 8, z + 4, ModBlocks.metadataBlocks, 3, 2);
		world.setBlock(x + 8, y + 8, z + 5, ModBlocks.metadataBlocks, 7, 2);
		world.setBlock(x + 8, y + 8, z + 6, ModBlocks.metadataBlocks, 7, 2);
		world.setBlock(x + 8, y + 8, z + 7, ModBlocks.metadataBlocks, 7, 2);
		world.setBlock(x + 8, y + 8, z + 8, Blocks.obsidian);
		world.setBlock(x + 8, y + 9, z + 3, ModBlocks.metadataBlocks, 2, 2);
		world.setBlock(x + 8, y + 9, z + 4, Blocks.obsidian);
		world.setBlock(x + 8, y + 9, z + 5, ModBlocks.metadataBlocks, 7, 2);
		world.setBlock(x + 8, y + 9, z + 6, ModBlocks.metadataBlocks, 7, 2);
		world.setBlock(x + 8, y + 9, z + 7, ModBlocks.metadataBlocks, 2, 2);
		world.setBlock(x + 9, y + 1, z + 3, ModBlocks.metadataBlocks, 7, 2);
		world.setBlock(x + 9, y + 2, z + 2, ModBlocks.metadataBlocks, 7, 2);
		world.setBlock(x + 9, y + 2, z + 3, ModBlocks.metadataBlocks, 7, 2);
		world.setBlock(x + 9, y + 2, z + 4, Blocks.obsidian);
		world.setBlock(x + 9, y + 2, z + 5, Blocks.obsidian);
		world.setBlock(x + 9, y + 2, z + 6, Blocks.obsidian);
		world.setBlock(x + 9, y + 2, z + 7, Blocks.obsidian);
		world.setBlock(x + 9, y + 2, z + 9, ModBlocks.metadataBlocks, 7, 2);
		world.setBlock(x + 9, y + 3, z + 2, ModBlocks.metadataBlocks, 7, 2);
		world.setBlock(x + 9, y + 3, z + 3, ModBlocks.metadataBlocks, 7, 2);
		world.setBlock(x + 9, y + 3, z + 4, ModBlocks.metadataBlocks, 3, 2);
		world.setBlock(x + 9, y + 3, z + 5, ModBlocks.metadataBlocks, 3, 2);
		world.setBlock(x + 9, y + 3, z + 7, Blocks.obsidian);
		world.setBlock(x + 9, y + 3, z + 8, ModBlocks.metadataBlocks, 7, 2);
		world.setBlock(x + 9, y + 3, z + 9, ModBlocks.metadataBlocks, 7, 2);
		world.setBlock(x + 9, y + 4, z + 2, ModBlocks.metadataBlocks, 7, 2);
		world.setBlock(x + 9, y + 4, z + 3, ModBlocks.metadataBlocks, 3, 2);
		world.setBlock(x + 9, y + 4, z + 4, ModBlocks.metadataBlocks, 3, 2);
		world.setBlock(x + 9, y + 4, z + 5, ModBlocks.metadataBlocks, 7, 2);
		world.setBlock(x + 9, y + 4, z + 6, ModBlocks.metadataBlocks, 3, 2);
		world.setBlock(x + 9, y + 4, z + 8, ModBlocks.metadataBlocks, 7, 2);
		world.setBlock(x + 9, y + 4, z + 9, ModBlocks.metadataBlocks, 7, 2);
		world.setBlock(x + 9, y + 5, z + 2, Blocks.obsidian);
		world.setBlock(x + 9, y + 5, z + 3, ModBlocks.metadataBlocks, 7, 2);
		world.setBlock(x + 9, y + 5, z + 4, ModBlocks.metadataBlocks, 7, 2);
		world.setBlock(x + 9, y + 5, z + 5, ModBlocks.metadataBlocks, 7, 2);
		world.setBlock(x + 9, y + 5, z + 6, ModBlocks.metadataBlocks, 7, 2);
		world.setBlock(x + 9, y + 5, z + 7, ModBlocks.metadataBlocks, 3, 2);
		world.setBlock(x + 9, y + 5, z + 8, ModBlocks.metadataBlocks, 7, 2);
		world.setBlock(x + 9, y + 5, z + 9, ModBlocks.metadataBlocks, 7, 2);
		world.setBlock(x + 9, y + 6, z + 2, ModBlocks.metadataBlocks, 3, 2);
		world.setBlock(x + 9, y + 6, z + 4, ModBlocks.metadataBlocks, 7, 2);
		world.setBlock(x + 9, y + 6, z + 5, ModBlocks.metadataBlocks, 7, 2);
		world.setBlock(x + 9, y + 6, z + 6, ModBlocks.metadataBlocks, 7, 2);
		world.setBlock(x + 9, y + 6, z + 7, ModBlocks.metadataBlocks, 7, 2);
		world.setBlock(x + 9, y + 6, z + 8, ModBlocks.metadataBlocks, 7, 2);
		world.setBlock(x + 9, y + 7, z + 2, Blocks.obsidian);
		world.setBlock(x + 9, y + 7, z + 3, Blocks.obsidian);
		world.setBlock(x + 9, y + 7, z + 5, ModBlocks.metadataBlocks, 7, 2);
		world.setBlock(x + 9, y + 7, z + 6, ModBlocks.metadataBlocks, 7, 2);
		world.setBlock(x + 9, y + 7, z + 7, ModBlocks.metadataBlocks, 7, 2);
		world.setBlock(x + 9, y + 7, z + 8, ModBlocks.metadataBlocks, 7, 2);
		world.setBlock(x + 9, y + 8, z + 3, Blocks.obsidian);
		world.setBlock(x + 9, y + 8, z + 4, Blocks.obsidian);
		world.setBlock(x + 9, y + 8, z + 5, ModBlocks.metadataBlocks, 7, 2);
		world.setBlock(x + 9, y + 8, z + 6, ModBlocks.metadataBlocks, 7, 2);
		world.setBlock(x + 9, y + 8, z + 7, ModBlocks.metadataBlocks, 7, 2);
		world.setBlock(x + 10, y + 3, z + 3, ModBlocks.metadataBlocks, 7, 2);
		world.setBlock(x + 10, y + 3, z + 4, ModBlocks.metadataBlocks, 7, 2);
		world.setBlock(x + 10, y + 3, z + 5, ModBlocks.metadataBlocks, 3, 2);
		world.setBlock(x + 10, y + 3, z + 6, Blocks.obsidian);
		world.setBlock(x + 10, y + 4, z + 3, ModBlocks.metadataBlocks, 7, 2);
		world.setBlock(x + 10, y + 4, z + 4, ModBlocks.metadataBlocks, 7, 2);
		world.setBlock(x + 10, y + 4, z + 5, ModBlocks.metadataBlocks, 3, 2);
		world.setBlock(x + 10, y + 4, z + 6, Blocks.obsidian);
		world.setBlock(x + 10, y + 4, z + 7, Blocks.obsidian);
		world.setBlock(x + 10, y + 4, z + 8, ModBlocks.metadataBlocks, 7, 2);
		world.setBlock(x + 10, y + 5, z + 3, ModBlocks.metadataBlocks, 7, 2);
		world.setBlock(x + 10, y + 5, z + 4, ModBlocks.metadataBlocks, 7, 2);
		world.setBlock(x + 10, y + 5, z + 5, ModBlocks.metadataBlocks, 3, 2);
		world.setBlock(x + 10, y + 5, z + 6, ModBlocks.metadataBlocks, 7, 2);
		world.setBlock(x + 10, y + 5, z + 7, ModBlocks.metadataBlocks, 7, 2);
		world.setBlock(x + 10, y + 5, z + 8, ModBlocks.metadataBlocks, 2, 2);
		world.setBlock(x + 10, y + 6, z + 3, ModBlocks.metadataBlocks, 3, 2);
		world.setBlock(x + 10, y + 6, z + 4, ModBlocks.metadataBlocks, 7, 2);
		world.setBlock(x + 10, y + 6, z + 5, ModBlocks.metadataBlocks, 7, 2);
		world.setBlock(x + 10, y + 6, z + 6, ModBlocks.metadataBlocks, 7, 2);
		world.setBlock(x + 10, y + 6, z + 7, ModBlocks.metadataBlocks, 7, 2);
		world.setBlock(x + 10, y + 7, z + 4, ModBlocks.metadataBlocks, 7, 2);
		world.setBlock(x + 10, y + 7, z + 5, ModBlocks.metadataBlocks, 3, 2);
		world.setBlock(x + 10, y + 7, z + 6, ModBlocks.metadataBlocks, 3, 2);
		world.setBlock(x + 10, y + 7, z + 7, ModBlocks.metadataBlocks, 7, 2);
		return true;
	}
	
	public boolean generate1(World world, Random rand, int x, int y, int z){
		world.setBlock(x + 0, y + 3, z + 4, Blocks.obsidian);
		world.setBlock(x + 0, y + 3, z + 5, Blocks.obsidian);
		world.setBlock(x + 0, y + 3, z + 6, Blocks.obsidian);
		world.setBlock(x + 0, y + 4, z + 3, Blocks.obsidian);
		world.setBlock(x + 0, y + 4, z + 4, Blocks.obsidian);
		world.setBlock(x + 0, y + 4, z + 5, Blocks.obsidian);
		world.setBlock(x + 0, y + 4, z + 6, Blocks.obsidian);
		world.setBlock(x + 0, y + 4, z + 7, Blocks.obsidian);
		world.setBlock(x + 0, y + 5, z + 6, Blocks.obsidian);
		world.setBlock(x + 0, y + 5, z + 7, Blocks.obsidian);
		world.setBlock(x + 0, y + 6, z + 3, Blocks.obsidian);
		world.setBlock(x + 0, y + 6, z + 4, Blocks.obsidian);
		world.setBlock(x + 0, y + 6, z + 5, ModBlocks.metadataBlocks, 7, 2);
		world.setBlock(x + 0, y + 6, z + 6, Blocks.obsidian);
		world.setBlock(x + 0, y + 6, z + 7, Blocks.obsidian);
		world.setBlock(x + 0, y + 7, z + 4, ModBlocks.metadataBlocks, 7, 2);
		world.setBlock(x + 0, y + 7, z + 5, Blocks.obsidian);
		world.setBlock(x + 0, y + 7, z + 6, Blocks.obsidian);
		world.setBlock(x + 1, y + 2, z + 3, Blocks.obsidian);
		world.setBlock(x + 1, y + 2, z + 4, ModBlocks.metadataBlocks, 2, 2);
		world.setBlock(x + 1, y + 2, z + 5, ModBlocks.metadataBlocks, 2, 2);
		world.setBlock(x + 1, y + 2, z + 6, ModBlocks.metadataBlocks, 2, 2);
		world.setBlock(x + 1, y + 2, z + 7, ModBlocks.metadataBlocks, 7, 2);
		world.setBlock(x + 1, y + 3, z + 2, Blocks.obsidian);
		world.setBlock(x + 1, y + 3, z + 3, ModBlocks.metadataBlocks, 2, 2);
		world.setBlock(x + 1, y + 3, z + 4, ModBlocks.metadataBlocks, 2, 2);
		world.setBlock(x + 1, y + 3, z + 5, ModBlocks.metadataBlocks, 2, 2);
		world.setBlock(x + 1, y + 3, z + 6, ModBlocks.metadataBlocks, 2, 2);
		world.setBlock(x + 1, y + 3, z + 7, ModBlocks.metadataBlocks, 2, 2);
		world.setBlock(x + 1, y + 3, z + 8, Blocks.obsidian);
		world.setBlock(x + 1, y + 4, z + 2, Blocks.obsidian);
		world.setBlock(x + 1, y + 4, z + 3, ModBlocks.metadataBlocks, 2, 2);
		world.setBlock(x + 1, y + 4, z + 4, ModBlocks.metadataBlocks, 7, 2);
		world.setBlock(x + 1, y + 4, z + 5, ModBlocks.metadataBlocks, 2, 2);
		world.setBlock(x + 1, y + 4, z + 6, ModBlocks.metadataBlocks, 2, 2);
		world.setBlock(x + 1, y + 4, z + 7, ModBlocks.metadataBlocks, 7, 2);
		world.setBlock(x + 1, y + 4, z + 8, Blocks.obsidian);
		world.setBlock(x + 1, y + 5, z + 2, ModBlocks.metadataBlocks, 7, 2);
		world.setBlock(x + 1, y + 5, z + 6, ModBlocks.metadataBlocks, 7, 2);
		world.setBlock(x + 1, y + 5, z + 7, ModBlocks.metadataBlocks, 2, 2);
		world.setBlock(x + 1, y + 6, z + 2, Blocks.obsidian);
		world.setBlock(x + 1, y + 6, z + 4, ModBlocks.metadataBlocks, 7, 2);
		world.setBlock(x + 1, y + 6, z + 5, ModBlocks.metadataBlocks, 3, 2);
		world.setBlock(x + 1, y + 6, z + 6, ModBlocks.metadataBlocks, 7, 2);
		world.setBlock(x + 1, y + 6, z + 7, ModBlocks.metadataBlocks, 2, 2);
		world.setBlock(x + 1, y + 6, z + 8, ModBlocks.metadataBlocks, 7, 2);
		world.setBlock(x + 1, y + 7, z + 2, Blocks.obsidian);
		world.setBlock(x + 1, y + 7, z + 3, Blocks.obsidian);
		world.setBlock(x + 1, y + 7, z + 5, ModBlocks.metadataBlocks, 7, 2);
		world.setBlock(x + 1, y + 7, z + 7, ModBlocks.metadataBlocks, 2, 2);
		world.setBlock(x + 1, y + 7, z + 8, Blocks.obsidian);
		world.setBlock(x + 1, y + 8, z + 3, Blocks.obsidian);
		world.setBlock(x + 1, y + 8, z + 4, Blocks.obsidian);
		world.setBlock(x + 1, y + 8, z + 5, Blocks.obsidian);
		world.setBlock(x + 1, y + 8, z + 6, Blocks.obsidian);
		world.setBlock(x + 1, y + 8, z + 7, Blocks.obsidian);
		world.setBlock(x + 2, y + 1, z + 3, Blocks.obsidian);
		world.setBlock(x + 2, y + 1, z + 4, ModBlocks.metadataBlocks, 2, 2);
		world.setBlock(x + 2, y + 1, z + 5, ModBlocks.metadataBlocks, 2, 2);
		world.setBlock(x + 2, y + 1, z + 6, Blocks.obsidian);
		world.setBlock(x + 2, y + 1, z + 7, Blocks.obsidian);
		world.setBlock(x + 2, y + 2, z + 2, Blocks.obsidian);
		world.setBlock(x + 2, y + 2, z + 3, ModBlocks.metadataBlocks, 7, 2);
		world.setBlock(x + 2, y + 2, z + 4, ModBlocks.metadataBlocks, 2, 2);
		world.setBlock(x + 2, y + 2, z + 5, ModBlocks.metadataBlocks, 7, 2);
		world.setBlock(x + 2, y + 2, z + 6, ModBlocks.metadataBlocks, 2, 2);
		world.setBlock(x + 2, y + 2, z + 8, Blocks.obsidian);
		world.setBlock(x + 2, y + 3, z + 1, Blocks.obsidian);
		world.setBlock(x + 2, y + 3, z + 2, ModBlocks.metadataBlocks, 2, 2);
		world.setBlock(x + 2, y + 3, z + 3, ModBlocks.metadataBlocks, 2, 2);
		world.setBlock(x + 2, y + 3, z + 4, ModBlocks.metadataBlocks, 2, 2);
		world.setBlock(x + 2, y + 3, z + 5, ModBlocks.metadataBlocks, 2, 2);
		world.setBlock(x + 2, y + 3, z + 6, ModBlocks.metadataBlocks, 2, 2);
		world.setBlock(x + 2, y + 3, z + 7, ModBlocks.metadataBlocks, 7, 2);
		world.setBlock(x + 2, y + 3, z + 9, Blocks.obsidian);
		world.setBlock(x + 2, y + 4, z + 1, Blocks.obsidian);
		world.setBlock(x + 2, y + 4, z + 2, ModBlocks.metadataBlocks, 2, 2);
		world.setBlock(x + 2, y + 4, z + 3, ModBlocks.metadataBlocks, 7, 2);
		world.setBlock(x + 2, y + 4, z + 4, ModBlocks.metadataBlocks, 2, 2);
		world.setBlock(x + 2, y + 4, z + 5, ModBlocks.metadataBlocks, 2, 2);
		world.setBlock(x + 2, y + 4, z + 6, ModBlocks.metadataBlocks, 2, 2);
		world.setBlock(x + 2, y + 4, z + 7, ModBlocks.metadataBlocks, 2, 2);
		world.setBlock(x + 2, y + 4, z + 8, ModBlocks.metadataBlocks, 7, 2);
		world.setBlock(x + 2, y + 4, z + 9, Blocks.obsidian);
		world.setBlock(x + 2, y + 5, z + 1, Blocks.obsidian);
		world.setBlock(x + 2, y + 5, z + 2, ModBlocks.metadataBlocks, 2, 2);
		world.setBlock(x + 2, y + 5, z + 3, ModBlocks.metadataBlocks, 7, 2);
		world.setBlock(x + 2, y + 5, z + 4, ModBlocks.metadataBlocks, 7, 2);
		world.setBlock(x + 2, y + 5, z + 9, ModBlocks.metadataBlocks, 3, 2);
		world.setBlock(x + 2, y + 6, z + 1, Blocks.obsidian);
		world.setBlock(x + 2, y + 6, z + 2, ModBlocks.metadataBlocks, 2, 2);
		world.setBlock(x + 2, y + 6, z + 3, ModBlocks.metadataBlocks, 7, 2);
		world.setBlock(x + 2, y + 6, z + 4, ModBlocks.metadataBlocks, 7, 2);
		world.setBlock(x + 2, y + 6, z + 5, ModBlocks.metadataBlocks, 7, 2);
		world.setBlock(x + 2, y + 6, z + 6, ModBlocks.metadataBlocks, 7, 2);
		world.setBlock(x + 2, y + 6, z + 7, ModBlocks.metadataBlocks, 2, 2);
		world.setBlock(x + 2, y + 6, z + 8, ModBlocks.metadataBlocks, 2, 2);
		world.setBlock(x + 2, y + 6, z + 9, Blocks.obsidian);
		world.setBlock(x + 2, y + 7, z + 1, Blocks.obsidian);
		world.setBlock(x + 2, y + 7, z + 3, ModBlocks.metadataBlocks, 7, 2);
		world.setBlock(x + 2, y + 7, z + 4, ModBlocks.metadataBlocks, 7, 2);
		world.setBlock(x + 2, y + 7, z + 5, ModBlocks.metadataBlocks, 7, 2);
		world.setBlock(x + 2, y + 7, z + 6, ModBlocks.metadataBlocks, 7, 2);
		world.setBlock(x + 2, y + 7, z + 7, ModBlocks.metadataBlocks, 2, 2);
		world.setBlock(x + 2, y + 7, z + 8, ModBlocks.metadataBlocks, 2, 2);
		world.setBlock(x + 2, y + 7, z + 9, Blocks.obsidian);
		world.setBlock(x + 2, y + 8, z + 2, Blocks.obsidian);
		world.setBlock(x + 2, y + 8, z + 4, ModBlocks.metadataBlocks, 7, 2);
		world.setBlock(x + 2, y + 8, z + 5, ModBlocks.metadataBlocks, 7, 2);
		world.setBlock(x + 2, y + 8, z + 6, ModBlocks.metadataBlocks, 7, 2);
		world.setBlock(x + 2, y + 8, z + 8, Blocks.obsidian);
		world.setBlock(x + 2, y + 9, z + 3, Blocks.obsidian);
		world.setBlock(x + 2, y + 9, z + 4, Blocks.obsidian);
		world.setBlock(x + 2, y + 9, z + 5, Blocks.obsidian);
		world.setBlock(x + 2, y + 9, z + 6, Blocks.obsidian);
		world.setBlock(x + 2, y + 9, z + 7, Blocks.obsidian);
		world.setBlock(x + 3, y + 0, z + 4, ModBlocks.metadataBlocks, 2, 2);
		world.setBlock(x + 3, y + 0, z + 5, ModBlocks.metadataBlocks, 2, 2);
		world.setBlock(x + 3, y + 0, z + 6, ModBlocks.metadataBlocks, 2, 2);
		world.setBlock(x + 3, y + 1, z + 2, Blocks.obsidian);
		world.setBlock(x + 3, y + 1, z + 3, Blocks.obsidian);
		world.setBlock(x + 3, y + 1, z + 4, ModBlocks.metadataBlocks, 2, 2);
		world.setBlock(x + 3, y + 1, z + 5, ModBlocks.metadataBlocks, 2, 2);
		world.setBlock(x + 3, y + 1, z + 6, ModBlocks.metadataBlocks, 2, 2);
		world.setBlock(x + 3, y + 1, z + 7, Blocks.obsidian);
		world.setBlock(x + 3, y + 1, z + 8, ModBlocks.metadataBlocks, 7, 2);
		world.setBlock(x + 3, y + 2, z + 1, Blocks.obsidian);
		world.setBlock(x + 3, y + 2, z + 3, ModBlocks.metadataBlocks, 7, 2);
		world.setBlock(x + 3, y + 2, z + 4, ModBlocks.metadataBlocks, 2, 2);
		world.setBlock(x + 3, y + 2, z + 5, ModBlocks.metadataBlocks, 2, 2);
		world.setBlock(x + 3, y + 2, z + 6, ModBlocks.metadataBlocks, 7, 2);
		world.setBlock(x + 3, y + 2, z + 7, ModBlocks.metadataBlocks, 7, 2);
		world.setBlock(x + 3, y + 2, z + 9, Blocks.obsidian);
		world.setBlock(x + 3, y + 3, z + 1, Blocks.obsidian);
		world.setBlock(x + 3, y + 3, z + 2, ModBlocks.metadataBlocks, 7, 2);
		world.setBlock(x + 3, y + 3, z + 3, ModBlocks.metadataBlocks, 2, 2);
		world.setBlock(x + 3, y + 3, z + 4, ModBlocks.metadataBlocks, 2, 2);
		world.setBlock(x + 3, y + 3, z + 5, ModBlocks.metadataBlocks, 2, 2);
		world.setBlock(x + 3, y + 3, z + 6, ModBlocks.metadataBlocks, 2, 2);
		world.setBlock(x + 3, y + 3, z + 7, ModBlocks.metadataBlocks, 7, 2);
		world.setBlock(x + 3, y + 3, z + 8, ModBlocks.metadataBlocks, 7, 2);
		world.setBlock(x + 3, y + 3, z + 9, Blocks.obsidian);
		world.setBlock(x + 3, y + 4, z + 0, Blocks.obsidian);
		world.setBlock(x + 3, y + 4, z + 1, ModBlocks.metadataBlocks, 2, 2);
		world.setBlock(x + 3, y + 4, z + 2, ModBlocks.metadataBlocks, 2, 2);
		world.setBlock(x + 3, y + 4, z + 3, ModBlocks.metadataBlocks, 2, 2);
		world.setBlock(x + 3, y + 4, z + 4, ModBlocks.metadataBlocks, 7, 2);
		world.setBlock(x + 3, y + 4, z + 5, ModBlocks.metadataBlocks, 2, 2);
		world.setBlock(x + 3, y + 4, z + 6, ModBlocks.metadataBlocks, 2, 2);
		world.setBlock(x + 3, y + 4, z + 7, ModBlocks.metadataBlocks, 7, 2);
		world.setBlock(x + 3, y + 4, z + 8, ModBlocks.metadataBlocks, 7, 2);
		world.setBlock(x + 3, y + 4, z + 10, Blocks.obsidian);
		world.setBlock(x + 3, y + 5, z + 0, Blocks.obsidian);
		world.setBlock(x + 3, y + 5, z + 1, ModBlocks.metadataBlocks, 2, 2);
		world.setBlock(x + 3, y + 5, z + 2, ModBlocks.metadataBlocks, 2, 2);
		world.setBlock(x + 3, y + 5, z + 3, ModBlocks.metadataBlocks, 2, 2);
		world.setBlock(x + 3, y + 5, z + 4, ModBlocks.metadataBlocks, 2, 2);
		world.setBlock(x + 3, y + 5, z + 6, ModBlocks.metadataBlocks, 7, 2);
		world.setBlock(x + 3, y + 6, z + 0, ModBlocks.metadataBlocks, 7, 2);
		world.setBlock(x + 3, y + 6, z + 2, ModBlocks.metadataBlocks, 2, 2);
		world.setBlock(x + 3, y + 6, z + 3, ModBlocks.metadataBlocks, 2, 2);
		world.setBlock(x + 3, y + 6, z + 4, ModBlocks.metadataBlocks, 7, 2);
		world.setBlock(x + 3, y + 6, z + 5, ModBlocks.metadataBlocks, 7, 2);
		world.setBlock(x + 3, y + 6, z + 6, ModBlocks.metadataBlocks, 2, 2);
		world.setBlock(x + 3, y + 6, z + 7, ModBlocks.metadataBlocks, 2, 2);
		world.setBlock(x + 3, y + 6, z + 8, ModBlocks.metadataBlocks, 2, 2);
		world.setBlock(x + 3, y + 6, z + 9, ModBlocks.metadataBlocks, 2, 2);
		world.setBlock(x + 3, y + 6, z + 10, ModBlocks.metadataBlocks, 2, 2);
		world.setBlock(x + 3, y + 7, z + 1, Blocks.obsidian);
		world.setBlock(x + 3, y + 7, z + 2, ModBlocks.metadataBlocks, 7, 2);
		world.setBlock(x + 3, y + 7, z + 3, ModBlocks.metadataBlocks, 7, 2);
		world.setBlock(x + 3, y + 7, z + 4, ModBlocks.metadataBlocks, 7, 2);
		world.setBlock(x + 3, y + 7, z + 5, ModBlocks.metadataBlocks, 7, 2);
		world.setBlock(x + 3, y + 7, z + 6, ModBlocks.metadataBlocks, 7, 2);
		world.setBlock(x + 3, y + 7, z + 7, ModBlocks.metadataBlocks, 2, 2);
		world.setBlock(x + 3, y + 7, z + 8, ModBlocks.metadataBlocks, 2, 2);
		world.setBlock(x + 3, y + 7, z + 9, ModBlocks.metadataBlocks, 2, 2);
		world.setBlock(x + 3, y + 8, z + 1, Blocks.obsidian);
		world.setBlock(x + 3, y + 8, z + 3, ModBlocks.metadataBlocks, 7, 2);
		world.setBlock(x + 3, y + 8, z + 4, ModBlocks.metadataBlocks, 7, 2);
		world.setBlock(x + 3, y + 8, z + 5, ModBlocks.metadataBlocks, 7, 2);
		world.setBlock(x + 3, y + 8, z + 6, ModBlocks.metadataBlocks, 7, 2);
		world.setBlock(x + 3, y + 8, z + 7, ModBlocks.metadataBlocks, 2, 2);
		world.setBlock(x + 3, y + 8, z + 8, ModBlocks.metadataBlocks, 7, 2);
		world.setBlock(x + 3, y + 8, z + 9, Blocks.obsidian);
		world.setBlock(x + 3, y + 9, z + 2, Blocks.obsidian);
		world.setBlock(x + 3, y + 9, z + 3, Blocks.obsidian);
		world.setBlock(x + 3, y + 9, z + 5, ModBlocks.metadataBlocks, 7, 2);
		world.setBlock(x + 3, y + 9, z + 7, ModBlocks.metadataBlocks, 2, 2);
		world.setBlock(x + 3, y + 9, z + 8, Blocks.obsidian);
		world.setBlock(x + 3, y + 10, z + 4, Blocks.obsidian);
		world.setBlock(x + 3, y + 10, z + 5, Blocks.obsidian);
		world.setBlock(x + 3, y + 10, z + 6, Blocks.obsidian);
		world.setBlock(x + 4, y + 0, z + 3, Blocks.obsidian);
		world.setBlock(x + 4, y + 0, z + 4, ModBlocks.metadataBlocks, 2, 2);
		world.setBlock(x + 4, y + 0, z + 5, ModBlocks.metadataBlocks, 2, 2);
		world.setBlock(x + 4, y + 0, z + 6, ModBlocks.metadataBlocks, 2, 2);
		world.setBlock(x + 4, y + 0, z + 7, Blocks.obsidian);
		world.setBlock(x + 4, y + 1, z + 2, Blocks.obsidian);
		world.setBlock(x + 4, y + 1, z + 4, ModBlocks.metadataBlocks, 2, 2);
		world.setBlock(x + 4, y + 1, z + 5, ModBlocks.metadataBlocks, 7, 2);
		world.setBlock(x + 4, y + 1, z + 6, ModBlocks.metadataBlocks, 2, 2);
		world.setBlock(x + 4, y + 1, z + 8, Blocks.obsidian);
		world.setBlock(x + 4, y + 2, z + 1, Blocks.obsidian);
		world.setBlock(x + 4, y + 2, z + 2, ModBlocks.metadataBlocks, 7, 2);
		world.setBlock(x + 4, y + 2, z + 3, ModBlocks.metadataBlocks, 7, 2);
		world.setBlock(x + 4, y + 2, z + 4, ModBlocks.metadataBlocks, 2, 2);
		world.setBlock(x + 4, y + 2, z + 5, ModBlocks.metadataBlocks, 2, 2);
		world.setBlock(x + 4, y + 2, z + 6, ModBlocks.metadataBlocks, 2, 2);
		world.setBlock(x + 4, y + 2, z + 7, ModBlocks.metadataBlocks, 7, 2);
		world.setBlock(x + 4, y + 2, z + 8, ModBlocks.metadataBlocks, 7, 2);
		world.setBlock(x + 4, y + 2, z + 9, Blocks.obsidian);
		world.setBlock(x + 4, y + 3, z + 0, Blocks.obsidian);
		world.setBlock(x + 4, y + 3, z + 2, ModBlocks.metadataBlocks, 7, 2);
		world.setBlock(x + 4, y + 3, z + 3, ModBlocks.metadataBlocks, 7, 2);
		world.setBlock(x + 4, y + 3, z + 4, ModBlocks.metadataBlocks, 2, 2);
		world.setBlock(x + 4, y + 3, z + 5, ModBlocks.metadataBlocks, 2, 2);
		world.setBlock(x + 4, y + 3, z + 6, ModBlocks.metadataBlocks, 2, 2);
		world.setBlock(x + 4, y + 3, z + 7, ModBlocks.metadataBlocks, 7, 2);
		world.setBlock(x + 4, y + 3, z + 8, ModBlocks.metadataBlocks, 7, 2);
		world.setBlock(x + 4, y + 3, z + 10, Blocks.obsidian);
		world.setBlock(x + 4, y + 4, z + 0, Blocks.obsidian);
		world.setBlock(x + 4, y + 4, z + 1, ModBlocks.metadataBlocks, 7, 2);
		world.setBlock(x + 4, y + 4, z + 2, ModBlocks.metadataBlocks, 7, 2);
		world.setBlock(x + 4, y + 4, z + 3, ModBlocks.metadataBlocks, 2, 2);
		world.setBlock(x + 4, y + 4, z + 4, ModBlocks.metadataBlocks, 2, 2);
		world.setBlock(x + 4, y + 4, z + 5, ModBlocks.metadataBlocks, 2, 2);
		world.setBlock(x + 4, y + 4, z + 6, ModBlocks.metadataBlocks, 2, 2);
		world.setBlock(x + 4, y + 4, z + 7, ModBlocks.metadataBlocks, 7, 2);
		world.setBlock(x + 4, y + 4, z + 8, ModBlocks.metadataBlocks, 2, 2);
		world.setBlock(x + 4, y + 4, z + 9, ModBlocks.metadataBlocks, 2, 2);
		world.setBlock(x + 4, y + 4, z + 10, ModBlocks.metadataBlocks, 7, 2);
		world.setBlock(x + 4, y + 5, z + 0, Blocks.obsidian);
		world.setBlock(x + 4, y + 5, z + 1, ModBlocks.metadataBlocks, 7, 2);
		world.setBlock(x + 4, y + 5, z + 2, ModBlocks.metadataBlocks, 2, 2);
		world.setBlock(x + 4, y + 5, z + 3, ModBlocks.metadataBlocks, 2, 2);
		world.setBlock(x + 4, y + 5, z + 4, ModBlocks.metadataBlocks, 2, 2);
		world.setBlock(x + 4, y + 5, z + 8, ModBlocks.metadataBlocks, 2, 2);
		world.setBlock(x + 4, y + 6, z + 0, Blocks.obsidian);
		world.setBlock(x + 4, y + 6, z + 1, ModBlocks.metadataBlocks, 2, 2);
		world.setBlock(x + 4, y + 6, z + 2, ModBlocks.metadataBlocks, 2, 2);
		world.setBlock(x + 4, y + 6, z + 3, ModBlocks.metadataBlocks, 2, 2);
		world.setBlock(x + 4, y + 6, z + 4, ModBlocks.metadataBlocks, 7, 2);
		world.setBlock(x + 4, y + 6, z + 5, ModBlocks.metadataBlocks, 7, 2);
		world.setBlock(x + 4, y + 6, z + 6, ModBlocks.metadataBlocks, 2, 2);
		world.setBlock(x + 4, y + 6, z + 7, ModBlocks.metadataBlocks, 2, 2);
		world.setBlock(x + 4, y + 6, z + 8, ModBlocks.metadataBlocks, 2, 2);
		world.setBlock(x + 4, y + 6, z + 9, ModBlocks.metadataBlocks, 2, 2);
		world.setBlock(x + 4, y + 6, z + 10, ModBlocks.metadataBlocks, 2, 2);
		world.setBlock(x + 4, y + 7, z + 0, Blocks.obsidian);
		world.setBlock(x + 4, y + 7, z + 1, ModBlocks.metadataBlocks, 2, 2);
		world.setBlock(x + 4, y + 7, z + 2, ModBlocks.metadataBlocks, 2, 2);
		world.setBlock(x + 4, y + 7, z + 3, ModBlocks.metadataBlocks, 7, 2);
		world.setBlock(x + 4, y + 7, z + 4, ModBlocks.metadataBlocks, 2, 2);
		world.setBlock(x + 4, y + 7, z + 5, ModBlocks.metadataBlocks, 7, 2);
		world.setBlock(x + 4, y + 7, z + 6, ModBlocks.metadataBlocks, 2, 2);
		world.setBlock(x + 4, y + 7, z + 7, ModBlocks.metadataBlocks, 7, 2);
		world.setBlock(x + 4, y + 7, z + 8, ModBlocks.metadataBlocks, 2, 2);
		world.setBlock(x + 4, y + 7, z + 9, ModBlocks.metadataBlocks, 2, 2);
		world.setBlock(x + 4, y + 7, z + 10, ModBlocks.metadataBlocks, 7, 2);
		world.setBlock(x + 4, y + 8, z + 1, Blocks.obsidian);
		world.setBlock(x + 4, y + 8, z + 2, ModBlocks.metadataBlocks, 2, 2);
		world.setBlock(x + 4, y + 8, z + 3, ModBlocks.metadataBlocks, 2, 2);
		world.setBlock(x + 4, y + 8, z + 4, ModBlocks.metadataBlocks, 2, 2);
		world.setBlock(x + 4, y + 8, z + 5, ModBlocks.metadataBlocks, 2, 2);
		world.setBlock(x + 4, y + 8, z + 6, ModBlocks.metadataBlocks, 2, 2);
		world.setBlock(x + 4, y + 8, z + 7, ModBlocks.metadataBlocks, 2, 2);
		world.setBlock(x + 4, y + 8, z + 8, ModBlocks.metadataBlocks, 2, 2);
		world.setBlock(x + 4, y + 8, z + 9, Blocks.obsidian);
		world.setBlock(x + 4, y + 9, z + 2, Blocks.obsidian);
		world.setBlock(x + 4, y + 9, z + 3, ModBlocks.metadataBlocks, 2, 2);
		world.setBlock(x + 4, y + 9, z + 4, ModBlocks.metadataBlocks, 2, 2);
		world.setBlock(x + 4, y + 9, z + 5, ModBlocks.metadataBlocks, 2, 2);
		world.setBlock(x + 4, y + 9, z + 6, ModBlocks.metadataBlocks, 2, 2);
		world.setBlock(x + 4, y + 9, z + 7, ModBlocks.metadataBlocks, 3, 2);
		world.setBlock(x + 4, y + 9, z + 8, ModBlocks.metadataBlocks, 2, 2);
		world.setBlock(x + 4, y + 10, z + 3, ModBlocks.metadataBlocks, 7, 2);
		world.setBlock(x + 4, y + 10, z + 4, Blocks.obsidian);
		world.setBlock(x + 4, y + 10, z + 5, Blocks.obsidian);
		world.setBlock(x + 4, y + 10, z + 6, Blocks.obsidian);
		world.setBlock(x + 4, y + 10, z + 7, Blocks.obsidian);
		world.setBlock(x + 5, y + 0, z + 3, Blocks.obsidian);
		world.setBlock(x + 5, y + 0, z + 4, Blocks.obsidian);
		world.setBlock(x + 5, y + 0, z + 5, ModBlocks.metadataBlocks, 2, 2);
		world.setBlock(x + 5, y + 0, z + 6, ModBlocks.metadataBlocks, 2, 2);
		world.setBlock(x + 5, y + 0, z + 7, ModBlocks.metadataBlocks, 2, 2);
		world.setBlock(x + 5, y + 1, z + 2, Blocks.obsidian);
		world.setBlock(x + 5, y + 1, z + 3, ModBlocks.metadataBlocks, 3, 2);
		world.setBlock(x + 5, y + 1, z + 4, ModBlocks.metadataBlocks, 7, 2);
		world.setBlock(x + 5, y + 1, z + 5, ModBlocks.metadataBlocks, 2, 2);
		world.setBlock(x + 5, y + 1, z + 6, ModBlocks.metadataBlocks, 2, 2);
		world.setBlock(x + 5, y + 1, z + 7, ModBlocks.metadataBlocks, 2, 2);
		world.setBlock(x + 5, y + 1, z + 8, Blocks.obsidian);
		world.setBlock(x + 5, y + 2, z + 1, Blocks.obsidian);
		world.setBlock(x + 5, y + 2, z + 2, ModBlocks.metadataBlocks, 7, 2);
		world.setBlock(x + 5, y + 2, z + 3, ModBlocks.metadataBlocks, 7, 2);
		world.setBlock(x + 5, y + 2, z + 4, ModBlocks.metadataBlocks, 7, 2);
		world.setBlock(x + 5, y + 2, z + 5, ModBlocks.metadataBlocks, 2, 2);
		world.setBlock(x + 5, y + 2, z + 6, ModBlocks.metadataBlocks, 2, 2);
		world.setBlock(x + 5, y + 2, z + 7, ModBlocks.metadataBlocks, 2, 2);
		world.setBlock(x + 5, y + 2, z + 8, ModBlocks.metadataBlocks, 7, 2);
		world.setBlock(x + 5, y + 2, z + 9, ModBlocks.metadataBlocks, 7, 2);
		world.setBlock(x + 5, y + 2, z + 10, ModBlocks.metadataBlocks, 2, 2);
		world.setBlock(x + 5, y + 3, z + 0, Blocks.obsidian);
		world.setBlock(x + 5, y + 3, z + 1, ModBlocks.metadataBlocks, 7, 2);
		world.setBlock(x + 5, y + 3, z + 2, ModBlocks.metadataBlocks, 7, 2);
		world.setBlock(x + 5, y + 3, z + 3, ModBlocks.metadataBlocks, 7, 2);
		world.setBlock(x + 5, y + 3, z + 4, ModBlocks.metadataBlocks, 7, 2);
		world.setBlock(x + 5, y + 3, z + 5, ModBlocks.metadataBlocks, 2, 2);
		world.setBlock(x + 5, y + 3, z + 6, ModBlocks.metadataBlocks, 2, 2);
		world.setBlock(x + 5, y + 3, z + 7, ModBlocks.metadataBlocks, 2, 2);
		world.setBlock(x + 5, y + 3, z + 8, ModBlocks.metadataBlocks, 2, 2);
		world.setBlock(x + 5, y + 3, z + 9, ModBlocks.metadataBlocks, 2, 2);
		world.setBlock(x + 5, y + 3, z + 10, ModBlocks.metadataBlocks, 7, 2);
		world.setBlock(x + 5, y + 4, z + 0, Blocks.obsidian);
		world.setBlock(x + 5, y + 4, z + 1, ModBlocks.metadataBlocks, 7, 2);
		world.setBlock(x + 5, y + 4, z + 2, ModBlocks.metadataBlocks, 7, 2);
		world.setBlock(x + 5, y + 4, z + 3, ModBlocks.metadataBlocks, 3, 2);
		world.setBlock(x + 5, y + 4, z + 4, ModBlocks.metadataBlocks, 2, 2);
		world.setBlock(x + 5, y + 4, z + 5, ModBlocks.metadataBlocks, 2, 2);
		world.setBlock(x + 5, y + 4, z + 6, ModBlocks.metadataBlocks, 2, 2);
		world.setBlock(x + 5, y + 4, z + 7, ModBlocks.metadataBlocks, 2, 2);
		world.setBlock(x + 5, y + 4, z + 8, ModBlocks.metadataBlocks, 2, 2);
		world.setBlock(x + 5, y + 4, z + 9, ModBlocks.metadataBlocks, 2, 2);
		world.setBlock(x + 5, y + 4, z + 10, ModBlocks.metadataBlocks, 2, 2);
		world.setBlock(x + 5, y + 5, z + 0, Blocks.obsidian);
		world.setBlock(x + 5, y + 5, z + 1, ModBlocks.metadataBlocks, 7, 2);
		world.setBlock(x + 5, y + 5, z + 2, ModBlocks.metadataBlocks, 7, 2);
		world.setBlock(x + 5, y + 5, z + 3, ModBlocks.metadataBlocks, 2, 2);
		world.setBlock(x + 5, y + 5, z + 4, ModBlocks.metadataBlocks, 2, 2);
		world.setBlock(x + 5, y + 5, z + 7, ModBlocks.metadataBlocks, 7, 2);
		world.setBlock(x + 5, y + 5, z + 8, ModBlocks.metadataBlocks, 2, 2);
		world.setBlock(x + 5, y + 5, z + 9, ModBlocks.metadataBlocks, 2, 2);
		world.setBlock(x + 5, y + 5, z + 10, ModBlocks.metadataBlocks, 2, 2);
		world.setBlock(x + 5, y + 6, z + 0, Blocks.obsidian);
		world.setBlock(x + 5, y + 6, z + 1, ModBlocks.metadataBlocks, 2, 2);
		world.setBlock(x + 5, y + 6, z + 2, ModBlocks.metadataBlocks, 2, 2);
		world.setBlock(x + 5, y + 6, z + 3, ModBlocks.metadataBlocks, 2, 2);
		world.setBlock(x + 5, y + 6, z + 4, ModBlocks.metadataBlocks, 2, 2);
		world.setBlock(x + 5, y + 6, z + 5, ModBlocks.metadataBlocks, 2, 2);
		world.setBlock(x + 5, y + 6, z + 6, ModBlocks.metadataBlocks, 2, 2);
		world.setBlock(x + 5, y + 6, z + 7, ModBlocks.metadataBlocks, 2, 2);
		world.setBlock(x + 5, y + 6, z + 8, ModBlocks.metadataBlocks, 2, 2);
		world.setBlock(x + 5, y + 6, z + 9, ModBlocks.metadataBlocks, 2, 2);
		world.setBlock(x + 5, y + 6, z + 10, Blocks.obsidian);
		world.setBlock(x + 5, y + 7, z + 0, Blocks.obsidian);
		world.setBlock(x + 5, y + 7, z + 1, ModBlocks.metadataBlocks, 2, 2);
		world.setBlock(x + 5, y + 7, z + 2, ModBlocks.metadataBlocks, 2, 2);
		world.setBlock(x + 5, y + 7, z + 3, ModBlocks.metadataBlocks, 2, 2);
		world.setBlock(x + 5, y + 7, z + 4, ModBlocks.metadataBlocks, 2, 2);
		world.setBlock(x + 5, y + 7, z + 5, ModBlocks.metadataBlocks, 2, 2);
		world.setBlock(x + 5, y + 7, z + 6, ModBlocks.metadataBlocks, 2, 2);
		world.setBlock(x + 5, y + 7, z + 7, ModBlocks.metadataBlocks, 2, 2);
		world.setBlock(x + 5, y + 7, z + 8, ModBlocks.metadataBlocks, 7, 2);
		world.setBlock(x + 5, y + 7, z + 9, ModBlocks.metadataBlocks, 7, 2);
		world.setBlock(x + 5, y + 7, z + 10, Blocks.obsidian);
		world.setBlock(x + 5, y + 8, z + 1, Blocks.obsidian);
		world.setBlock(x + 5, y + 8, z + 2, ModBlocks.metadataBlocks, 2, 2);
		world.setBlock(x + 5, y + 8, z + 3, ModBlocks.metadataBlocks, 2, 2);
		world.setBlock(x + 5, y + 8, z + 4, ModBlocks.metadataBlocks, 2, 2);
		world.setBlock(x + 5, y + 8, z + 5, ModBlocks.metadataBlocks, 2, 2);
		world.setBlock(x + 5, y + 8, z + 6, ModBlocks.metadataBlocks, 7, 2);
		world.setBlock(x + 5, y + 8, z + 7, ModBlocks.metadataBlocks, 7, 2);
		world.setBlock(x + 5, y + 8, z + 8, ModBlocks.metadataBlocks, 7, 2);
		world.setBlock(x + 5, y + 8, z + 9, Blocks.obsidian);
		world.setBlock(x + 5, y + 9, z + 2, Blocks.obsidian);
		world.setBlock(x + 5, y + 9, z + 3, ModBlocks.metadataBlocks, 2, 2);
		world.setBlock(x + 5, y + 9, z + 4, ModBlocks.metadataBlocks, 2, 2);
		world.setBlock(x + 5, y + 9, z + 5, ModBlocks.metadataBlocks, 2, 2);
		world.setBlock(x + 5, y + 9, z + 6, ModBlocks.metadataBlocks, 3, 2);
		world.setBlock(x + 5, y + 9, z + 7, ModBlocks.metadataBlocks, 2, 2);
		world.setBlock(x + 5, y + 9, z + 8, Blocks.obsidian);
		world.setBlock(x + 5, y + 10, z + 3, Blocks.obsidian);
		world.setBlock(x + 5, y + 10, z + 4, ModBlocks.metadataBlocks, 7, 2);
		world.setBlock(x + 5, y + 10, z + 5, Blocks.obsidian);
		world.setBlock(x + 5, y + 10, z + 6, Blocks.obsidian);
		world.setBlock(x + 5, y + 10, z + 7, Blocks.obsidian);
		world.setBlock(x + 6, y + 0, z + 3, ModBlocks.metadataBlocks, 2, 2);
		world.setBlock(x + 6, y + 0, z + 4, ModBlocks.metadataBlocks, 2, 2);
		world.setBlock(x + 6, y + 0, z + 5, ModBlocks.metadataBlocks, 7, 2);
		world.setBlock(x + 6, y + 0, z + 6, ModBlocks.metadataBlocks, 2, 2);
		world.setBlock(x + 6, y + 0, z + 7, ModBlocks.metadataBlocks, 2, 2);
		world.setBlock(x + 6, y + 0, z + 8, ModBlocks.metadataBlocks, 2, 2);
		world.setBlock(x + 6, y + 1, z + 2, Blocks.obsidian);
		world.setBlock(x + 6, y + 1, z + 3, ModBlocks.metadataBlocks, 2, 2);
		world.setBlock(x + 6, y + 1, z + 4, ModBlocks.metadataBlocks, 2, 2);
		world.setBlock(x + 6, y + 1, z + 5, ModBlocks.metadataBlocks, 2, 2);
		world.setBlock(x + 6, y + 1, z + 6, ModBlocks.metadataBlocks, 2, 2);
		world.setBlock(x + 6, y + 1, z + 7, ModBlocks.metadataBlocks, 2, 2);
		world.setBlock(x + 6, y + 1, z + 8, ModBlocks.metadataBlocks, 2, 2);
		world.setBlock(x + 6, y + 1, z + 9, ModBlocks.metadataBlocks, 2, 2);
		world.setBlock(x + 6, y + 2, z + 1, Blocks.obsidian);
		world.setBlock(x + 6, y + 2, z + 2, ModBlocks.metadataBlocks, 7, 2);
		world.setBlock(x + 6, y + 2, z + 3, ModBlocks.metadataBlocks, 7, 2);
		world.setBlock(x + 6, y + 2, z + 4, ModBlocks.metadataBlocks, 2, 2);
		world.setBlock(x + 6, y + 2, z + 5, ModBlocks.metadataBlocks, 2, 2);
		world.setBlock(x + 6, y + 2, z + 6, ModBlocks.metadataBlocks, 7, 2);
		world.setBlock(x + 6, y + 2, z + 7, ModBlocks.metadataBlocks, 2, 2);
		world.setBlock(x + 6, y + 2, z + 8, ModBlocks.metadataBlocks, 2, 2);
		world.setBlock(x + 6, y + 2, z + 9, ModBlocks.metadataBlocks, 2, 2);
		world.setBlock(x + 6, y + 2, z + 10, ModBlocks.metadataBlocks, 2, 2);
		world.setBlock(x + 6, y + 3, z + 0, Blocks.obsidian);
		world.setBlock(x + 6, y + 3, z + 2, ModBlocks.metadataBlocks, 7, 2);
		world.setBlock(x + 6, y + 3, z + 3, ModBlocks.metadataBlocks, 7, 2);
		world.setBlock(x + 6, y + 3, z + 4, ModBlocks.metadataBlocks, 2, 2);
		world.setBlock(x + 6, y + 3, z + 5, ModBlocks.metadataBlocks, 2, 2);
		world.setBlock(x + 6, y + 3, z + 6, ModBlocks.metadataBlocks, 2, 2);
		world.setBlock(x + 6, y + 3, z + 7, ModBlocks.metadataBlocks, 2, 2);
		world.setBlock(x + 6, y + 3, z + 8, ModBlocks.metadataBlocks, 2, 2);
		world.setBlock(x + 6, y + 3, z + 9, ModBlocks.metadataBlocks, 2, 2);
		world.setBlock(x + 6, y + 3, z + 10, ModBlocks.metadataBlocks, 2, 2);
		world.setBlock(x + 6, y + 4, z + 0, Blocks.obsidian);
		world.setBlock(x + 6, y + 4, z + 1, ModBlocks.metadataBlocks, 2, 2);
		world.setBlock(x + 6, y + 4, z + 2, ModBlocks.metadataBlocks, 7, 2);
		world.setBlock(x + 6, y + 4, z + 3, ModBlocks.metadataBlocks, 2, 2);
		world.setBlock(x + 6, y + 4, z + 4, ModBlocks.metadataBlocks, 2, 2);
		world.setBlock(x + 6, y + 4, z + 5, ModBlocks.metadataBlocks, 2, 2);
		world.setBlock(x + 6, y + 4, z + 6, ModBlocks.metadataBlocks, 2, 2);
		world.setBlock(x + 6, y + 4, z + 7, ModBlocks.metadataBlocks, 7, 2);
		world.setBlock(x + 6, y + 4, z + 8, ModBlocks.metadataBlocks, 2, 2);
		world.setBlock(x + 6, y + 4, z + 9, ModBlocks.metadataBlocks, 2, 2);
		world.setBlock(x + 6, y + 4, z + 10, ModBlocks.metadataBlocks, 2, 2);
		world.setBlock(x + 6, y + 5, z + 0, Blocks.obsidian);
		world.setBlock(x + 6, y + 5, z + 1, ModBlocks.metadataBlocks, 2, 2);
		world.setBlock(x + 6, y + 5, z + 2, ModBlocks.metadataBlocks, 2, 2);
		world.setBlock(x + 6, y + 5, z + 3, ModBlocks.metadataBlocks, 2, 2);
		world.setBlock(x + 6, y + 5, z + 4, ModBlocks.metadataBlocks, 2, 2);
		world.setBlock(x + 6, y + 5, z + 5, ModBlocks.metadataBlocks, 2, 2);
		world.setBlock(x + 6, y + 5, z + 6, ModBlocks.metadataBlocks, 2, 2);
		world.setBlock(x + 6, y + 5, z + 7, ModBlocks.metadataBlocks, 7, 2);
		world.setBlock(x + 6, y + 5, z + 8, ModBlocks.metadataBlocks, 7, 2);
		world.setBlock(x + 6, y + 5, z + 9, ModBlocks.metadataBlocks, 7, 2);
		world.setBlock(x + 6, y + 5, z + 10, Blocks.obsidian);
		world.setBlock(x + 6, y + 6, z + 0, Blocks.obsidian);
		world.setBlock(x + 6, y + 6, z + 1, ModBlocks.metadataBlocks, 2, 2);
		world.setBlock(x + 6, y + 6, z + 2, ModBlocks.metadataBlocks, 2, 2);
		world.setBlock(x + 6, y + 6, z + 3, ModBlocks.metadataBlocks, 2, 2);
		world.setBlock(x + 6, y + 6, z + 4, ModBlocks.metadataBlocks, 2, 2);
		world.setBlock(x + 6, y + 6, z + 5, ModBlocks.metadataBlocks, 2, 2);
		world.setBlock(x + 6, y + 6, z + 6, ModBlocks.metadataBlocks, 2, 2);
		world.setBlock(x + 6, y + 6, z + 7, ModBlocks.metadataBlocks, 7, 2);
		world.setBlock(x + 6, y + 6, z + 8, ModBlocks.metadataBlocks, 7, 2);
		world.setBlock(x + 6, y + 6, z + 9, ModBlocks.metadataBlocks, 7, 2);
		world.setBlock(x + 6, y + 6, z + 10, ModBlocks.metadataBlocks, 7, 2);
		world.setBlock(x + 6, y + 7, z + 0, Blocks.obsidian);
		world.setBlock(x + 6, y + 7, z + 1, ModBlocks.metadataBlocks, 2, 2);
		world.setBlock(x + 6, y + 7, z + 2, ModBlocks.metadataBlocks, 2, 2);
		world.setBlock(x + 6, y + 7, z + 3, ModBlocks.metadataBlocks, 2, 2);
		world.setBlock(x + 6, y + 7, z + 4, ModBlocks.metadataBlocks, 2, 2);
		world.setBlock(x + 6, y + 7, z + 5, ModBlocks.metadataBlocks, 2, 2);
		world.setBlock(x + 6, y + 7, z + 6, ModBlocks.metadataBlocks, 2, 2);
		world.setBlock(x + 6, y + 7, z + 7, ModBlocks.metadataBlocks, 7, 2);
		world.setBlock(x + 6, y + 7, z + 8, ModBlocks.metadataBlocks, 7, 2);
		world.setBlock(x + 6, y + 7, z + 10, Blocks.obsidian);
		world.setBlock(x + 6, y + 8, z + 1, ModBlocks.metadataBlocks, 7, 2);
		world.setBlock(x + 6, y + 8, z + 2, ModBlocks.metadataBlocks, 7, 2);
		world.setBlock(x + 6, y + 8, z + 3, ModBlocks.metadataBlocks, 2, 2);
		world.setBlock(x + 6, y + 8, z + 4, ModBlocks.metadataBlocks, 2, 2);
		world.setBlock(x + 6, y + 8, z + 5, ModBlocks.metadataBlocks, 2, 2);
		world.setBlock(x + 6, y + 8, z + 6, ModBlocks.metadataBlocks, 2, 2);
		world.setBlock(x + 6, y + 8, z + 7, ModBlocks.metadataBlocks, 7, 2);
		world.setBlock(x + 6, y + 8, z + 8, ModBlocks.metadataBlocks, 7, 2);
		world.setBlock(x + 6, y + 8, z + 9, Blocks.obsidian);
		world.setBlock(x + 6, y + 9, z + 2, Blocks.obsidian);
		world.setBlock(x + 6, y + 9, z + 3, ModBlocks.metadataBlocks, 2, 2);
		world.setBlock(x + 6, y + 9, z + 4, ModBlocks.metadataBlocks, 2, 2);
		world.setBlock(x + 6, y + 9, z + 5, ModBlocks.metadataBlocks, 2, 2);
		world.setBlock(x + 6, y + 9, z + 6, ModBlocks.metadataBlocks, 7, 2);
		world.setBlock(x + 6, y + 9, z + 7, ModBlocks.metadataBlocks, 7, 2);
		world.setBlock(x + 6, y + 9, z + 8, Blocks.obsidian);
		world.setBlock(x + 6, y + 10, z + 3, Blocks.obsidian);
		world.setBlock(x + 6, y + 10, z + 4, Blocks.obsidian);
		world.setBlock(x + 6, y + 10, z + 5, Blocks.obsidian);
		world.setBlock(x + 6, y + 10, z + 6, Blocks.obsidian);
		world.setBlock(x + 6, y + 10, z + 7, Blocks.obsidian);
		world.setBlock(x + 7, y + 0, z + 3, ModBlocks.metadataBlocks, 2, 2);
		world.setBlock(x + 7, y + 0, z + 4, ModBlocks.metadataBlocks, 2, 2);
		world.setBlock(x + 7, y + 0, z + 5, ModBlocks.metadataBlocks, 2, 2);
		world.setBlock(x + 7, y + 0, z + 6, Blocks.obsidian);
		world.setBlock(x + 7, y + 0, z + 7, ModBlocks.metadataBlocks, 2, 2);
		world.setBlock(x + 7, y + 0, z + 8, ModBlocks.metadataBlocks, 2, 2);
		world.setBlock(x + 7, y + 1, z + 2, ModBlocks.metadataBlocks, 2, 2);
		world.setBlock(x + 7, y + 1, z + 3, ModBlocks.metadataBlocks, 2, 2);
		world.setBlock(x + 7, y + 1, z + 4, ModBlocks.metadataBlocks, 2, 2);
		world.setBlock(x + 7, y + 1, z + 5, ModBlocks.metadataBlocks, 2, 2);
		world.setBlock(x + 7, y + 1, z + 7, ModBlocks.metadataBlocks, 2, 2);
		world.setBlock(x + 7, y + 1, z + 8, ModBlocks.metadataBlocks, 3, 2);
		world.setBlock(x + 7, y + 1, z + 9, ModBlocks.metadataBlocks, 2, 2);
		world.setBlock(x + 7, y + 2, z + 1, Blocks.obsidian);
		world.setBlock(x + 7, y + 2, z + 2, ModBlocks.metadataBlocks, 2, 2);
		world.setBlock(x + 7, y + 2, z + 3, ModBlocks.metadataBlocks, 2, 2);
		world.setBlock(x + 7, y + 2, z + 4, ModBlocks.metadataBlocks, 2, 2);
		world.setBlock(x + 7, y + 2, z + 5, ModBlocks.metadataBlocks, 2, 2);
		world.setBlock(x + 7, y + 2, z + 6, ModBlocks.metadataBlocks, 3, 2);
		world.setBlock(x + 7, y + 2, z + 7, ModBlocks.metadataBlocks, 2, 2);
		world.setBlock(x + 7, y + 2, z + 8, ModBlocks.metadataBlocks, 7, 2);
		world.setBlock(x + 7, y + 2, z + 9, ModBlocks.metadataBlocks, 2, 2);
		world.setBlock(x + 7, y + 2, z + 10, ModBlocks.metadataBlocks, 2, 2);
		world.setBlock(x + 7, y + 3, z + 1, ModBlocks.metadataBlocks, 2, 2);
		world.setBlock(x + 7, y + 3, z + 2, ModBlocks.metadataBlocks, 2, 2);
		world.setBlock(x + 7, y + 3, z + 3, ModBlocks.metadataBlocks, 2, 2);
		world.setBlock(x + 7, y + 3, z + 4, ModBlocks.metadataBlocks, 2, 2);
		world.setBlock(x + 7, y + 3, z + 5, ModBlocks.metadataBlocks, 2, 2);
		world.setBlock(x + 7, y + 3, z + 6, ModBlocks.metadataBlocks, 7, 2);
		world.setBlock(x + 7, y + 3, z + 7, ModBlocks.metadataBlocks, 2, 2);
		world.setBlock(x + 7, y + 3, z + 8, ModBlocks.metadataBlocks, 2, 2);
		world.setBlock(x + 7, y + 3, z + 9, ModBlocks.metadataBlocks, 2, 2);
		world.setBlock(x + 7, y + 4, z + 0, Blocks.obsidian);
		world.setBlock(x + 7, y + 4, z + 1, ModBlocks.metadataBlocks, 7, 2);
		world.setBlock(x + 7, y + 4, z + 2, ModBlocks.metadataBlocks, 2, 2);
		world.setBlock(x + 7, y + 4, z + 3, ModBlocks.metadataBlocks, 2, 2);
		world.setBlock(x + 7, y + 4, z + 4, ModBlocks.metadataBlocks, 2, 2);
		world.setBlock(x + 7, y + 4, z + 5, ModBlocks.metadataBlocks, 2, 2);
		world.setBlock(x + 7, y + 4, z + 6, ModBlocks.metadataBlocks, 2, 2);
		world.setBlock(x + 7, y + 4, z + 7, ModBlocks.metadataBlocks, 2, 2);
		world.setBlock(x + 7, y + 4, z + 8, ModBlocks.metadataBlocks, 2, 2);
		world.setBlock(x + 7, y + 4, z + 10, Blocks.obsidian);
		world.setBlock(x + 7, y + 5, z + 0, ModBlocks.metadataBlocks, 7, 2);
		world.setBlock(x + 7, y + 5, z + 1, ModBlocks.metadataBlocks, 2, 2);
		world.setBlock(x + 7, y + 5, z + 2, ModBlocks.metadataBlocks, 2, 2);
		world.setBlock(x + 7, y + 5, z + 3, ModBlocks.metadataBlocks, 2, 2);
		world.setBlock(x + 7, y + 5, z + 4, ModBlocks.metadataBlocks, 7, 2);
		world.setBlock(x + 7, y + 5, z + 5, ModBlocks.metadataBlocks, 2, 2);
		world.setBlock(x + 7, y + 5, z + 6, ModBlocks.metadataBlocks, 2, 2);
		world.setBlock(x + 7, y + 5, z + 7, ModBlocks.metadataBlocks, 2, 2);
		world.setBlock(x + 7, y + 5, z + 8, ModBlocks.metadataBlocks, 7, 2);
		world.setBlock(x + 7, y + 5, z + 9, ModBlocks.metadataBlocks, 7, 2);
		world.setBlock(x + 7, y + 5, z + 10, Blocks.obsidian);
		world.setBlock(x + 7, y + 6, z + 0, Blocks.obsidian);
		world.setBlock(x + 7, y + 6, z + 1, ModBlocks.metadataBlocks, 2, 2);
		world.setBlock(x + 7, y + 6, z + 2, ModBlocks.metadataBlocks, 2, 2);
		world.setBlock(x + 7, y + 6, z + 3, ModBlocks.metadataBlocks, 7, 2);
		world.setBlock(x + 7, y + 6, z + 4, ModBlocks.metadataBlocks, 7, 2);
		world.setBlock(x + 7, y + 6, z + 5, ModBlocks.metadataBlocks, 2, 2);
		world.setBlock(x + 7, y + 6, z + 6, ModBlocks.metadataBlocks, 2, 2);
		world.setBlock(x + 7, y + 6, z + 7, ModBlocks.metadataBlocks, 2, 2);
		world.setBlock(x + 7, y + 6, z + 8, ModBlocks.metadataBlocks, 7, 2);
		world.setBlock(x + 7, y + 6, z + 10, Blocks.obsidian);
		world.setBlock(x + 7, y + 7, z + 1, ModBlocks.metadataBlocks, 7, 2);
		world.setBlock(x + 7, y + 7, z + 2, ModBlocks.metadataBlocks, 7, 2);
		world.setBlock(x + 7, y + 7, z + 3, ModBlocks.metadataBlocks, 7, 2);
		world.setBlock(x + 7, y + 7, z + 4, ModBlocks.metadataBlocks, 7, 2);
		world.setBlock(x + 7, y + 7, z + 5, ModBlocks.metadataBlocks, 2, 2);
		world.setBlock(x + 7, y + 7, z + 6, ModBlocks.metadataBlocks, 3, 2);
		world.setBlock(x + 7, y + 7, z + 7, ModBlocks.metadataBlocks, 2, 2);
		world.setBlock(x + 7, y + 7, z + 8, ModBlocks.metadataBlocks, 7, 2);
		world.setBlock(x + 7, y + 7, z + 9, ModBlocks.metadataBlocks, 7, 2);
		world.setBlock(x + 7, y + 8, z + 1, Blocks.obsidian);
		world.setBlock(x + 7, y + 8, z + 3, ModBlocks.metadataBlocks, 7, 2);
		world.setBlock(x + 7, y + 8, z + 4, ModBlocks.metadataBlocks, 7, 2);
		world.setBlock(x + 7, y + 8, z + 5, ModBlocks.metadataBlocks, 2, 2);
		world.setBlock(x + 7, y + 8, z + 6, ModBlocks.metadataBlocks, 2, 2);
		world.setBlock(x + 7, y + 8, z + 7, ModBlocks.metadataBlocks, 7, 2);
		world.setBlock(x + 7, y + 8, z + 9, Blocks.obsidian);
		world.setBlock(x + 7, y + 9, z + 2, Blocks.obsidian);
		world.setBlock(x + 7, y + 9, z + 3, Blocks.obsidian);
		world.setBlock(x + 7, y + 9, z + 5, ModBlocks.metadataBlocks, 7, 2);
		world.setBlock(x + 7, y + 9, z + 6, ModBlocks.metadataBlocks, 2, 2);
		world.setBlock(x + 7, y + 9, z + 7, ModBlocks.metadataBlocks, 2, 2);
		world.setBlock(x + 7, y + 9, z + 8, Blocks.obsidian);
		world.setBlock(x + 7, y + 10, z + 4, Blocks.obsidian);
		world.setBlock(x + 7, y + 10, z + 5, Blocks.obsidian);
		world.setBlock(x + 7, y + 10, z + 6, ModBlocks.metadataBlocks, 3, 2);
		world.setBlock(x + 8, y + 0, z + 4, ModBlocks.metadataBlocks, 2, 2);
		world.setBlock(x + 8, y + 1, z + 2, ModBlocks.metadataBlocks, 2, 2);
		world.setBlock(x + 8, y + 1, z + 3, ModBlocks.metadataBlocks, 2, 2);
		world.setBlock(x + 8, y + 1, z + 4, ModBlocks.metadataBlocks, 2, 2);
		world.setBlock(x + 8, y + 1, z + 5, ModBlocks.metadataBlocks, 2, 2);
		world.setBlock(x + 8, y + 1, z + 6, Blocks.obsidian);
		world.setBlock(x + 8, y + 1, z + 7, Blocks.obsidian);
		world.setBlock(x + 8, y + 1, z + 9, ModBlocks.metadataBlocks, 2, 2);
		world.setBlock(x + 8, y + 2, z + 2, ModBlocks.metadataBlocks, 2, 2);
		world.setBlock(x + 8, y + 2, z + 3, ModBlocks.metadataBlocks, 2, 2);
		world.setBlock(x + 8, y + 2, z + 4, ModBlocks.metadataBlocks, 2, 2);
		world.setBlock(x + 8, y + 2, z + 5, ModBlocks.metadataBlocks, 7, 2);
		world.setBlock(x + 8, y + 2, z + 6, ModBlocks.metadataBlocks, 7, 2);
		world.setBlock(x + 8, y + 2, z + 8, ModBlocks.metadataBlocks, 2, 2);
		world.setBlock(x + 8, y + 2, z + 9, ModBlocks.metadataBlocks, 2, 2);
		world.setBlock(x + 8, y + 2, z + 10, ModBlocks.metadataBlocks, 2, 2);
		world.setBlock(x + 8, y + 3, z + 1, ModBlocks.metadataBlocks, 2, 2);
		world.setBlock(x + 8, y + 3, z + 2, ModBlocks.metadataBlocks, 2, 2);
		world.setBlock(x + 8, y + 3, z + 3, ModBlocks.metadataBlocks, 2, 2);
		world.setBlock(x + 8, y + 3, z + 4, ModBlocks.metadataBlocks, 2, 2);
		world.setBlock(x + 8, y + 3, z + 5, ModBlocks.metadataBlocks, 7, 2);
		world.setBlock(x + 8, y + 3, z + 6, ModBlocks.metadataBlocks, 7, 2);
		world.setBlock(x + 8, y + 3, z + 7, ModBlocks.metadataBlocks, 7, 2);
		world.setBlock(x + 8, y + 3, z + 8, ModBlocks.metadataBlocks, 2, 2);
		world.setBlock(x + 8, y + 3, z + 9, ModBlocks.metadataBlocks, 2, 2);
		world.setBlock(x + 8, y + 3, z + 10, ModBlocks.metadataBlocks, 2, 2);
		world.setBlock(x + 8, y + 4, z + 1, ModBlocks.metadataBlocks, 2, 2);
		world.setBlock(x + 8, y + 4, z + 2, ModBlocks.metadataBlocks, 2, 2);
		world.setBlock(x + 8, y + 4, z + 3, ModBlocks.metadataBlocks, 2, 2);
		world.setBlock(x + 8, y + 4, z + 4, ModBlocks.metadataBlocks, 2, 2);
		world.setBlock(x + 8, y + 4, z + 5, ModBlocks.metadataBlocks, 2, 2);
		world.setBlock(x + 8, y + 4, z + 6, ModBlocks.metadataBlocks, 7, 2);
		world.setBlock(x + 8, y + 4, z + 7, ModBlocks.metadataBlocks, 2, 2);
		world.setBlock(x + 8, y + 4, z + 8, ModBlocks.metadataBlocks, 2, 2);
		world.setBlock(x + 8, y + 4, z + 9, ModBlocks.metadataBlocks, 2, 2);
		world.setBlock(x + 8, y + 5, z + 1, ModBlocks.metadataBlocks, 2, 2);
		world.setBlock(x + 8, y + 5, z + 2, ModBlocks.metadataBlocks, 7, 2);
		world.setBlock(x + 8, y + 5, z + 3, ModBlocks.metadataBlocks, 3, 2);
		world.setBlock(x + 8, y + 5, z + 4, ModBlocks.metadataBlocks, 2, 2);
		world.setBlock(x + 8, y + 5, z + 5, ModBlocks.metadataBlocks, 2, 2);
		world.setBlock(x + 8, y + 5, z + 6, ModBlocks.metadataBlocks, 7, 2);
		world.setBlock(x + 8, y + 5, z + 7, ModBlocks.metadataBlocks, 2, 2);
		world.setBlock(x + 8, y + 5, z + 8, ModBlocks.metadataBlocks, 3, 2);
		world.setBlock(x + 8, y + 5, z + 9, Blocks.obsidian);
		world.setBlock(x + 8, y + 6, z + 1, Blocks.obsidian);
		world.setBlock(x + 8, y + 6, z + 2, ModBlocks.metadataBlocks, 7, 2);
		world.setBlock(x + 8, y + 6, z + 3, ModBlocks.metadataBlocks, 7, 2);
		world.setBlock(x + 8, y + 6, z + 4, ModBlocks.metadataBlocks, 7, 2);
		world.setBlock(x + 8, y + 6, z + 5, ModBlocks.metadataBlocks, 2, 2);
		world.setBlock(x + 8, y + 6, z + 6, ModBlocks.metadataBlocks, 2, 2);
		world.setBlock(x + 8, y + 6, z + 7, ModBlocks.metadataBlocks, 2, 2);
		world.setBlock(x + 8, y + 6, z + 8, ModBlocks.metadataBlocks, 7, 2);
		world.setBlock(x + 8, y + 6, z + 9, Blocks.obsidian);
		world.setBlock(x + 8, y + 7, z + 1, Blocks.obsidian);
		world.setBlock(x + 8, y + 7, z + 3, ModBlocks.metadataBlocks, 7, 2);
		world.setBlock(x + 8, y + 7, z + 4, ModBlocks.metadataBlocks, 7, 2);
		world.setBlock(x + 8, y + 7, z + 5, ModBlocks.metadataBlocks, 2, 2);
		world.setBlock(x + 8, y + 7, z + 6, ModBlocks.metadataBlocks, 2, 2);
		world.setBlock(x + 8, y + 7, z + 7, ModBlocks.metadataBlocks, 2, 2);
		world.setBlock(x + 8, y + 7, z + 9, Blocks.obsidian);
		world.setBlock(x + 8, y + 8, z + 2, Blocks.obsidian);
		world.setBlock(x + 8, y + 8, z + 4, ModBlocks.metadataBlocks, 7, 2);
		world.setBlock(x + 8, y + 8, z + 5, ModBlocks.metadataBlocks, 2, 2);
		world.setBlock(x + 8, y + 8, z + 6, ModBlocks.metadataBlocks, 2, 2);
		world.setBlock(x + 8, y + 8, z + 7, ModBlocks.metadataBlocks, 2, 2);
		world.setBlock(x + 8, y + 8, z + 8, Blocks.obsidian);
		world.setBlock(x + 8, y + 9, z + 3, ModBlocks.metadataBlocks, 3, 2);
		world.setBlock(x + 8, y + 9, z + 4, Blocks.obsidian);
		world.setBlock(x + 8, y + 9, z + 5, ModBlocks.metadataBlocks, 2, 2);
		world.setBlock(x + 8, y + 9, z + 6, ModBlocks.metadataBlocks, 2, 2);
		world.setBlock(x + 8, y + 9, z + 7, ModBlocks.metadataBlocks, 3, 2);
		world.setBlock(x + 9, y + 1, z + 3, ModBlocks.metadataBlocks, 2, 2);
		world.setBlock(x + 9, y + 2, z + 2, ModBlocks.metadataBlocks, 2, 2);
		world.setBlock(x + 9, y + 2, z + 3, ModBlocks.metadataBlocks, 2, 2);
		world.setBlock(x + 9, y + 2, z + 4, Blocks.obsidian);
		world.setBlock(x + 9, y + 2, z + 5, Blocks.obsidian);
		world.setBlock(x + 9, y + 2, z + 6, Blocks.obsidian);
		world.setBlock(x + 9, y + 2, z + 7, Blocks.obsidian);
		world.setBlock(x + 9, y + 2, z + 9, ModBlocks.metadataBlocks, 2, 2);
		world.setBlock(x + 9, y + 3, z + 2, ModBlocks.metadataBlocks, 2, 2);
		world.setBlock(x + 9, y + 3, z + 3, ModBlocks.metadataBlocks, 2, 2);
		world.setBlock(x + 9, y + 3, z + 4, ModBlocks.metadataBlocks, 7, 2);
		world.setBlock(x + 9, y + 3, z + 5, ModBlocks.metadataBlocks, 7, 2);
		world.setBlock(x + 9, y + 3, z + 7, Blocks.obsidian);
		world.setBlock(x + 9, y + 3, z + 8, ModBlocks.metadataBlocks, 2, 2);
		world.setBlock(x + 9, y + 3, z + 9, ModBlocks.metadataBlocks, 2, 2);
		world.setBlock(x + 9, y + 4, z + 2, ModBlocks.metadataBlocks, 2, 2);
		world.setBlock(x + 9, y + 4, z + 3, ModBlocks.metadataBlocks, 7, 2);
		world.setBlock(x + 9, y + 4, z + 4, ModBlocks.metadataBlocks, 7, 2);
		world.setBlock(x + 9, y + 4, z + 5, ModBlocks.metadataBlocks, 2, 2);
		world.setBlock(x + 9, y + 4, z + 6, ModBlocks.metadataBlocks, 7, 2);
		world.setBlock(x + 9, y + 4, z + 8, ModBlocks.metadataBlocks, 2, 2);
		world.setBlock(x + 9, y + 4, z + 9, ModBlocks.metadataBlocks, 2, 2);
		world.setBlock(x + 9, y + 5, z + 2, Blocks.obsidian);
		world.setBlock(x + 9, y + 5, z + 3, ModBlocks.metadataBlocks, 2, 2);
		world.setBlock(x + 9, y + 5, z + 4, ModBlocks.metadataBlocks, 2, 2);
		world.setBlock(x + 9, y + 5, z + 5, ModBlocks.metadataBlocks, 2, 2);
		world.setBlock(x + 9, y + 5, z + 6, ModBlocks.metadataBlocks, 2, 2);
		world.setBlock(x + 9, y + 5, z + 7, ModBlocks.metadataBlocks, 7, 2);
		world.setBlock(x + 9, y + 5, z + 8, ModBlocks.metadataBlocks, 2, 2);
		world.setBlock(x + 9, y + 5, z + 9, ModBlocks.metadataBlocks, 2, 2);
		world.setBlock(x + 9, y + 6, z + 2, ModBlocks.metadataBlocks, 7, 2);
		world.setBlock(x + 9, y + 6, z + 4, ModBlocks.metadataBlocks, 2, 2);
		world.setBlock(x + 9, y + 6, z + 5, ModBlocks.metadataBlocks, 2, 2);
		world.setBlock(x + 9, y + 6, z + 6, ModBlocks.metadataBlocks, 2, 2);
		world.setBlock(x + 9, y + 6, z + 7, ModBlocks.metadataBlocks, 2, 2);
		world.setBlock(x + 9, y + 6, z + 8, ModBlocks.metadataBlocks, 2, 2);
		world.setBlock(x + 9, y + 7, z + 2, Blocks.obsidian);
		world.setBlock(x + 9, y + 7, z + 3, Blocks.obsidian);
		world.setBlock(x + 9, y + 7, z + 5, ModBlocks.metadataBlocks, 2, 2);
		world.setBlock(x + 9, y + 7, z + 6, ModBlocks.metadataBlocks, 2, 2);
		world.setBlock(x + 9, y + 7, z + 7, ModBlocks.metadataBlocks, 2, 2);
		world.setBlock(x + 9, y + 7, z + 8, ModBlocks.metadataBlocks, 2, 2);
		world.setBlock(x + 9, y + 8, z + 3, Blocks.obsidian);
		world.setBlock(x + 9, y + 8, z + 4, Blocks.obsidian);
		world.setBlock(x + 9, y + 8, z + 5, ModBlocks.metadataBlocks, 2, 2);
		world.setBlock(x + 9, y + 8, z + 6, ModBlocks.metadataBlocks, 2, 2);
		world.setBlock(x + 9, y + 8, z + 7, ModBlocks.metadataBlocks, 2, 2);
		world.setBlock(x + 10, y + 3, z + 3, ModBlocks.metadataBlocks, 2, 2);
		world.setBlock(x + 10, y + 3, z + 4, ModBlocks.metadataBlocks, 2, 2);
		world.setBlock(x + 10, y + 3, z + 5, ModBlocks.metadataBlocks, 7, 2);
		world.setBlock(x + 10, y + 3, z + 6, Blocks.obsidian);
		world.setBlock(x + 10, y + 4, z + 3, ModBlocks.metadataBlocks, 2, 2);
		world.setBlock(x + 10, y + 4, z + 4, ModBlocks.metadataBlocks, 2, 2);
		world.setBlock(x + 10, y + 4, z + 5, ModBlocks.metadataBlocks, 7, 2);
		world.setBlock(x + 10, y + 4, z + 6, Blocks.obsidian);
		world.setBlock(x + 10, y + 4, z + 7, Blocks.obsidian);
		world.setBlock(x + 10, y + 4, z + 8, ModBlocks.metadataBlocks, 2, 2);
		world.setBlock(x + 10, y + 5, z + 3, ModBlocks.metadataBlocks, 2, 2);
		world.setBlock(x + 10, y + 5, z + 4, ModBlocks.metadataBlocks, 2, 2);
		world.setBlock(x + 10, y + 5, z + 5, ModBlocks.metadataBlocks, 7, 2);
		world.setBlock(x + 10, y + 5, z + 6, ModBlocks.metadataBlocks, 2, 2);
		world.setBlock(x + 10, y + 5, z + 7, ModBlocks.metadataBlocks, 2, 2);
		world.setBlock(x + 10, y + 5, z + 8, ModBlocks.metadataBlocks, 3, 2);
		world.setBlock(x + 10, y + 6, z + 3, ModBlocks.metadataBlocks, 7, 2);
		world.setBlock(x + 10, y + 6, z + 4, ModBlocks.metadataBlocks, 2, 2);
		world.setBlock(x + 10, y + 6, z + 5, ModBlocks.metadataBlocks, 2, 2);
		world.setBlock(x + 10, y + 6, z + 6, ModBlocks.metadataBlocks, 2, 2);
		world.setBlock(x + 10, y + 6, z + 7, ModBlocks.metadataBlocks, 2, 2);
		world.setBlock(x + 10, y + 7, z + 4, ModBlocks.metadataBlocks, 2, 2);
		world.setBlock(x + 10, y + 7, z + 5, ModBlocks.metadataBlocks, 7, 2);
		world.setBlock(x + 10, y + 7, z + 6, ModBlocks.metadataBlocks, 7, 2);
		world.setBlock(x + 10, y + 7, z + 7, ModBlocks.metadataBlocks, 2, 2);
		
		return true;
	}
	
	public boolean generate2(World world, Random rand, int x, int y, int z){
		world.setBlock(x + 0, y + 3, z + 4, Blocks.obsidian);
		world.setBlock(x + 0, y + 3, z + 5, Blocks.obsidian);
		world.setBlock(x + 0, y + 3, z + 6, Blocks.obsidian);
		world.setBlock(x + 0, y + 4, z + 3, Blocks.obsidian);
		world.setBlock(x + 0, y + 4, z + 4, Blocks.obsidian);
		world.setBlock(x + 0, y + 4, z + 5, Blocks.obsidian);
		world.setBlock(x + 0, y + 4, z + 6, Blocks.obsidian);
		world.setBlock(x + 0, y + 4, z + 7, Blocks.obsidian);
		world.setBlock(x + 0, y + 5, z + 3, Blocks.obsidian);
		world.setBlock(x + 0, y + 5, z + 4, ModBlocks.metadataBlocks, 7, 2);
		world.setBlock(x + 0, y + 5, z + 5, Blocks.obsidian);
		world.setBlock(x + 0, y + 5, z + 6, Blocks.obsidian);
		world.setBlock(x + 0, y + 5, z + 7, Blocks.obsidian);
		world.setBlock(x + 0, y + 6, z + 3, Blocks.obsidian);
		world.setBlock(x + 0, y + 6, z + 4, Blocks.obsidian);
